Workbook
Name Accesorios: OFFSET(#REF!,0,0,COUNTA(#REF!)-2,1)
Name Alcatel: Catalogo!$B$2:$B$10
Name Apple: Catalogo!$C$2:$C$209
Name GOOGLE: Catalogo!$N$2:$N$15
Name Hisense: Catalogo!$D$2:$D$10
Name Honor: Catalogo!$H$2:$H$84
Name Huawei: Catalogo!$E$2:$E$49
Name Marca: Catalogo!$A$2:$A$12
Name Motorola: Catalogo!$F$2:$F$100
Name NUBIA: Catalogo!$M$2:$M$3
Name OPPO: Catalogo!$J$2:$J$89
Name REALME: Catalogo!$L$2:$L$6
Name Samsung: Catalogo!$G$2:$G$183
Name Xiaomi: Catalogo!$I$2:$I$89
Name ZTE: Catalogo!$K$2:$K$10

Sheet Cotizador
B2: Cotizador Precios Ármalo Negocios
B4: FECHA PRECIO VIGENTE | C4: =TODAY() -> 46279
F5: PRECIO VIGENTE
B6: Marca | C6: SAMSUNG | F6: Activación & Renovación - AT&T Ármalo Negocios
F7: Plan | G7: 299 | H7: 399 | I7: 499 | J7: 599 | K7: 799 | L7: 1299 | M7: 1499
B8: Equipo | C8: SAMSUNG GALAXY S26 FE 256GB 5G | F8: 12 Meses | G8: =IF(SUMIFS(Precios!$G:$G,Precios!$E:$E,$C$8,Precios!$AP:$AP,"<="&$C$4,Precios!$AQ:$AQ,">="&$C$4)>=0,SUMIFS(Precios!$G:$G,Precios!$E:$E,$C$8,Precios!$AP:$AP,"<="&$C$4,Precios!$AQ:$AQ,">="&$C$4)) -> 12989 | H8: =IF(SUMIFS(Precios!$L:$L,Precios!$E:$E,$C$8,Precios!$AP:$AP,"<="&$C$4,Precios!$AQ:$AQ,">="&$C$4)>=0,SUMIFS(Precios!$L:$L,Precios!$E:$E,$C$8,Precios!$AP:$AP,"<="&$C$4,Precios!$AQ:$AQ,">="&$C$4)) -> 12839 | I8: =IF(SUMIFS(Precios!$Q:$Q,Precios!$E:$E,$C$8,Precios!$AP:$AP,"<="&$C$4,Precios!$AQ:$AQ,">="&$C$4)>=0,SUMIFS(Precios!$Q:$Q,Precios!$E:$E,$C$8,Precios!$AP:$AP,"<="&$C$4,Precios!$AQ:$AQ,">="&$C$4)) -> 12689 | J8: =IF(SUMIFS(Precios!$V:$V,Precios!$E:$E,$C$8,Precios!$AP:$AP,"<="&$C$4,Precios!$AQ:$AQ,">="&$C$4)>=0,SUMIFS(Precios!$V:$V,Precios!$E:$E,$C$8,Precios!$AP:$AP,"<="&$C$4,Precios!$AQ:$AQ,">="&$C$4)) -> 12539 | K8: =IF(SUMIFS(Precios!$AA:$AA,Precios!$E:$E,$C$8,Precios!$AP:$AP,"<="&$C$4,Precios!$AQ:$AQ,">="&$C$4)>=0,SUMIFS(Precios!$AA:$AA,Precios!$E:$E,$C$8,Precios!$AP:$AP,"<="&$C$4,Precios!$AQ:$AQ,">="&$C$4)) -> 12229 | L8: =IF(SUMIFS(Precios!$AF:$AF,Precios!$E:$E,$C$8,Precios!$AP:$AP,"<="&$C$4,Precios!$AQ:$AQ,">="&$C$4)>=0,SUMIFS(Precios!$AF:$AF,Precios!$E:$E,$C$8,Precios!$AP:$AP,"<="&$C$4,Precios!$AQ:$AQ,">="&$C$4)) -> 11479 | M8: =IF(SUMIFS(Precios!$AK:$AK,Precios!$E:$E,$C$8,Precios!$AP:$AP,"<="&$C$4,Precios!$AQ:$AQ,">="&$C$4)>=0,SUMIFS(Precios!$AK:$AK,Precios!$E:$E,$C$8,Precios!$AP:$AP,"<="&$C$4,Precios!$AQ:$AQ,">="&$C$4)) -> 11169
F9: 18 Meses | G9: =IF(SUMIFS(Precios!$H:$H,Precios!$E:$E,$C$8,Precios!$AP:$AP,"<="&$C$4,Precios!$AQ:$AQ,">="&$C$4)>=0,SUMIFS(Precios!$H:$H,Precios!$E:$E,$C$8,Precios!$AP:$AP,"<="&$C$4,Precios!$AQ:$AQ,">="&$C$4)) -> 12759 | H9: =IF(SUMIFS(Precios!$M:$M,Precios!$E:$E,$C$8,Precios!$AP:$AP,"<="&$C$4,Precios!$AQ:$AQ,">="&$C$4)>=0,SUMIFS(Precios!$M:$M,Precios!$E:$E,$C$8,Precios!$AP:$AP,"<="&$C$4,Precios!$AQ:$AQ,">="&$C$4)) -> 12539 | I9: =IF(SUMIFS(Precios!$R:$R,Precios!$E:$E,$C$8,Precios!$AP:$AP,"<="&$C$4,Precios!$AQ:$AQ,">="&$C$4)>=0,SUMIFS(Precios!$R:$R,Precios!$E:$E,$C$8,Precios!$AP:$AP,"<="&$C$4,Precios!$AQ:$AQ,">="&$C$4)) -> 12309 | J9: =IF(SUMIFS(Precios!$W:$W,Precios!$E:$E,$C$8,Precios!$AP:$AP,"<="&$C$4,Precios!$AQ:$AQ,">="&$C$4)>=0,SUMIFS(Precios!$W:$W,Precios!$E:$E,$C$8,Precios!$AP:$AP,"<="&$C$4,Precios!$AQ:$AQ,">="&$C$4)) -> 12079 | K9: =IF(SUMIFS(Precios!$AB:$AB,Precios!$E:$E,$C$8,Precios!$AP:$AP,"<="&$C$4,Precios!$AQ:$AQ,">="&$C$4)>=0,SUMIFS(Precios!$AB:$AB,Precios!$E:$E,$C$8,Precios!$AP:$AP,"<="&$C$4,Precios!$AQ:$AQ,">="&$C$4)) -> 11629 | L9: =IF(SUMIFS(Precios!$AG:$AG,Precios!$E:$E,$C$8,Precios!$AP:$AP,"<="&$C$4,Precios!$AQ:$AQ,">="&$C$4)>=0,SUMIFS(Precios!$AG:$AG,Precios!$E:$E,$C$8,Precios!$AP:$AP,"<="&$C$4,Precios!$AQ:$AQ,">="&$C$4)) -> 10489 | M9: =IF(SUMIFS(Precios!$AL:$AL,Precios!$E:$E,$C$8,Precios!$AP:$AP,"<="&$C$4,Precios!$AQ:$AQ,">="&$C$4)>=0,SUMIFS(Precios!$AL:$AL,Precios!$E:$E,$C$8,Precios!$AP:$AP,"<="&$C$4,Precios!$AQ:$AQ,">="&$C$4)) -> 10039
B10: PRECIO LISTA | C10: =VLOOKUP(C8,Precios!E:F,2,0) -> 19299 | F10: 24 Meses | G10: =IF(SUMIFS(Precios!$I:$I,Precios!$E:$E,$C$8,Precios!$AP:$AP,"<="&$C$4,Precios!$AQ:$AQ,">="&$C$4)>=0,SUMIFS(Precios!$I:$I,Precios!$E:$E,$C$8,Precios!$AP:$AP,"<="&$C$4,Precios!$AQ:$AQ,">="&$C$4)) -> 12539 | H10: =IF(SUMIFS(Precios!$N:$N,Precios!$E:$E,$C$8,Precios!$AP:$AP,"<="&$C$4,Precios!$AQ:$AQ,">="&$C$4)>=0,SUMIFS(Precios!$N:$N,Precios!$E:$E,$C$8,Precios!$AP:$AP,"<="&$C$4,Precios!$AQ:$AQ,">="&$C$4)) -> 12239 | I10: =IF(SUMIFS(Precios!$S:$S,Precios!$E:$E,$C$8,Precios!$AP:$AP,"<="&$C$4,Precios!$AQ:$AQ,">="&$C$4)>=0,SUMIFS(Precios!$S:$S,Precios!$E:$E,$C$8,Precios!$AP:$AP,"<="&$C$4,Precios!$AQ:$AQ,">="&$C$4)) -> 11929 | J10: =IF(SUMIFS(Precios!$X:$X,Precios!$E:$E,$C$8,Precios!$AP:$AP,"<="&$C$4,Precios!$AQ:$AQ,">="&$C$4)>=0,SUMIFS(Precios!$X:$X,Precios!$E:$E,$C$8,Precios!$AP:$AP,"<="&$C$4,Precios!$AQ:$AQ,">="&$C$4)) -> 11629 | K10: =IF(SUMIFS(Precios!$AC:$AC,Precios!$E:$E,$C$8,Precios!$AP:$AP,"<="&$C$4,Precios!$AQ:$AQ,">="&$C$4)>=0,SUMIFS(Precios!$AC:$AC,Precios!$E:$E,$C$8,Precios!$AP:$AP,"<="&$C$4,Precios!$AQ:$AQ,">="&$C$4)) -> 11019 | L10: =IF(SUMIFS(Precios!$AH:$AH,Precios!$E:$E,$C$8,Precios!$AP:$AP,"<="&$C$4,Precios!$AQ:$AQ,">="&$C$4)>=0,SUMIFS(Precios!$AH:$AH,Precios!$E:$E,$C$8,Precios!$AP:$AP,"<="&$C$4,Precios!$AQ:$AQ,">="&$C$4)) -> 9509 | M10: =IF(SUMIFS(Precios!$AM:$AM,Precios!$E:$E,$C$8,Precios!$AP:$AP,"<="&$C$4,Precios!$AQ:$AQ,">="&$C$4)>=0,SUMIFS(Precios!$AM:$AM,Precios!$E:$E,$C$8,Precios!$AP:$AP,"<="&$C$4,Precios!$AQ:$AQ,">="&$C$4)) -> 8899
F11: 36 Meses | G11: =IF(SUMIFS(Precios!$J:$J,Precios!$E:$E,$C$8,Precios!$AP:$AP,"<="&$C$4,Precios!$AQ:$AQ,">="&$C$4)>=0,SUMIFS(Precios!$J:$J,Precios!$E:$E,$C$8,Precios!$AP:$AP,"<="&$C$4,Precios!$AQ:$AQ,">="&$C$4)) -> 12089 | H11: =IF(SUMIFS(Precios!$O:$O,Precios!$E:$E,$C$8,Precios!$AP:$AP,"<="&$C$4,Precios!$AQ:$AQ,">="&$C$4)>=0,SUMIFS(Precios!$O:$O,Precios!$E:$E,$C$8,Precios!$AP:$AP,"<="&$C$4,Precios!$AQ:$AQ,">="&$C$4)) -> 11629 | I11: =IF(SUMIFS(Precios!$T:$T,Precios!$E:$E,$C$8,Precios!$AP:$AP,"<="&$C$4,Precios!$AQ:$AQ,">="&$C$4)>=0,SUMIFS(Precios!$T:$T,Precios!$E:$E,$C$8,Precios!$AP:$AP,"<="&$C$4,Precios!$AQ:$AQ,">="&$C$4)) -> 11179 | J11: =IF(SUMIFS(Precios!$Y:$Y,Precios!$E:$E,$C$8,Precios!$AP:$AP,"<="&$C$4,Precios!$AQ:$AQ,">="&$C$4)>=0,SUMIFS(Precios!$Y:$Y,Precios!$E:$E,$C$8,Precios!$AP:$AP,"<="&$C$4,Precios!$AQ:$AQ,">="&$C$4)) -> 10719 | K11: =IF(SUMIFS(Precios!$AD:$AD,Precios!$E:$E,$C$8,Precios!$AP:$AP,"<="&$C$4,Precios!$AQ:$AQ,">="&$C$4)>=0,SUMIFS(Precios!$AD:$AD,Precios!$E:$E,$C$8,Precios!$AP:$AP,"<="&$C$4,Precios!$AQ:$AQ,">="&$C$4)) -> 9809 | L11: =IF(SUMIFS(Precios!$AI:$AI,Precios!$E:$E,$C$8,Precios!$AP:$AP,"<="&$C$4,Precios!$AQ:$AQ,">="&$C$4)>=0,SUMIFS(Precios!$AI:$AI,Precios!$E:$E,$C$8,Precios!$AP:$AP,"<="&$C$4,Precios!$AQ:$AQ,">="&$C$4)) -> 7539 | M11: =IF(SUMIFS(Precios!$AN:$AN,Precios!$E:$E,$C$8,Precios!$AP:$AP,"<="&$C$4,Precios!$AQ:$AQ,">="&$C$4)>=0,SUMIFS(Precios!$AN:$AN,Precios!$E:$E,$C$8,Precios!$AP:$AP,"<="&$C$4,Precios!$AQ:$AQ,">="&$C$4)) -> 6629
B12: Precio Vigente - Vigencia Actual | F12: 48 Meses | G12: =IF(SUMIFS(Precios!$K:$K,Precios!$E:$E,$C$8,Precios!$AP:$AP,"<="&$C$4,Precios!$AQ:$AQ,">="&$C$4)>=0,SUMIFS(Precios!$K:$K,Precios!$E:$E,$C$8,Precios!$AP:$AP,"<="&$C$4,Precios!$AQ:$AQ,">="&$C$4)) -> 11629 | H12: =IF(SUMIFS(Precios!$P:$P,Precios!$E:$E,$C$8,Precios!$AP:$AP,"<="&$C$4,Precios!$AQ:$AQ,">="&$C$4)>=0,SUMIFS(Precios!$P:$P,Precios!$E:$E,$C$8,Precios!$AP:$AP,"<="&$C$4,Precios!$AQ:$AQ,">="&$C$4)) -> 11029 | I12: =IF(SUMIFS(Precios!$U:$U,Precios!$E:$E,$C$8,Precios!$AP:$AP,"<="&$C$4,Precios!$AQ:$AQ,">="&$C$4)>=0,SUMIFS(Precios!$U:$U,Precios!$E:$E,$C$8,Precios!$AP:$AP,"<="&$C$4,Precios!$AQ:$AQ,">="&$C$4)) -> 10419 | J12: =IF(SUMIFS(Precios!$Z:$Z,Precios!$E:$E,$C$8,Precios!$AP:$AP,"<="&$C$4,Precios!$AQ:$AQ,">="&$C$4)>=0,SUMIFS(Precios!$Z:$Z,Precios!$E:$E,$C$8,Precios!$AP:$AP,"<="&$C$4,Precios!$AQ:$AQ,">="&$C$4)) -> 9819 | K12: =IF(SUMIFS(Precios!$AE:$AE,Precios!$E:$E,$C$8,Precios!$AP:$AP,"<="&$C$4,Precios!$AQ:$AQ,">="&$C$4)>=0,SUMIFS(Precios!$AE:$AE,Precios!$E:$E,$C$8,Precios!$AP:$AP,"<="&$C$4,Precios!$AQ:$AQ,">="&$C$4)) -> 8599 | L12: =IF(SUMIFS(Precios!$AJ:$AJ,Precios!$E:$E,$C$8,Precios!$AP:$AP,"<="&$C$4,Precios!$AQ:$AQ,">="&$C$4)>=0,SUMIFS(Precios!$AJ:$AJ,Precios!$E:$E,$C$8,Precios!$AP:$AP,"<="&$C$4,Precios!$AQ:$AQ,">="&$C$4)) -> 5569 | M12: =IF(SUMIFS(Precios!$AO:$AO,Precios!$E:$E,$C$8,Precios!$AP:$AP,"<="&$C$4,Precios!$AQ:$AQ,">="&$C$4)>=0,SUMIFS(Precios!$AO:$AO,Precios!$E:$E,$C$8,Precios!$AP:$AP,"<="&$C$4,Precios!$AQ:$AQ,">="&$C$4)) -> 4359
B13: INICIO VIGENCIA | C13: FIN VIGENCIA
B14: =IF(SUMIFS(Precios!$AP:$AP,Precios!$E:$E,$C$8,Precios!$AP:$AP,"<="&$C$4,Precios!$AQ:$AQ,">="&$C$4)>=0,SUMIFS(Precios!$AP:$AP,Precios!$E:$E,$C$8,Precios!$AP:$AP,"<="&$C$4,Precios!$AQ:$AQ,">="&$C$4)) -> 46279 | C14: =IF(B16=DATEVALUE("01/01/2050"), "INDEFINIDO", B16) -> 46326
B15: FIN VIGENCIA*Ocultar | F15: PRÓXIMO PRECIO
B16: =IF(SUMIFS(Precios!$AQ:$AQ,Precios!$E:$E,$C$8,Precios!$AP:$AP,"<="&$C$4,Precios!$AQ:$AQ,">="&$C$4)>=0,SUMIFS(Precios!$AQ:$AQ,Precios!$E:$E,$C$8,Precios!$AP:$AP,"<="&$C$4,Precios!$AQ:$AQ,">="&$C$4)) -> 46326 | F16: Activación & Renovación - AT&T Ármalo Negocios
B17: Próximo Precio - Vigencia Próxima Inmediata | F17: Plan | G17: 299 | H17: 399 | I17: 499 | J17: 599 | K17: 799 | L17: 1299 | M17: 1499
B18: PRÓXIMO INICIO DE VIGENCIA | C18: =IF(B16<=DATEVALUE("01/12/2026"), B16+1, "NA") -> 46327 | F18: 12 Meses | G18: =IF(B16<DATEVALUE("01/01/2050"),IF(SUMIFS(Precios!$G:$G,Precios!$E:$E,$C$8,Precios!$AP:$AP,"<="&$C$18,Precios!$AQ:$AQ,">="&$C$18)>=0,SUMIFS(Precios!$G:$G,Precios!$E:$E,$C$8,Precios!$AP:$AP,"<="&$C$18,Precios!$AQ:$AQ,">="&$C$18)),"NA") -> 14989 | H18: =IF(B16<DATEVALUE("01/01/2050"),IF(SUMIFS(Precios!$L:$L,Precios!$E:$E,$C$8,Precios!$AP:$AP,"<="&$C$18,Precios!$AQ:$AQ,">="&$C$18)>=0,SUMIFS(Precios!$L:$L,Precios!$E:$E,$C$8,Precios!$AP:$AP,"<="&$C$18,Precios!$AQ:$AQ,">="&$C$18)),"NA") -> 14839 | I18: =IF(B16<DATEVALUE("01/01/2050"),IF(SUMIFS(Precios!$Q:$Q,Precios!$E:$E,$C$8,Precios!$AP:$AP,"<="&$C$18,Precios!$AQ:$AQ,">="&$C$18)>=0,SUMIFS(Precios!$Q:$Q,Precios!$E:$E,$C$8,Precios!$AP:$AP,"<="&$C$18,Precios!$AQ:$AQ,">="&$C$18)),"NA") -> 14689 | J18: =IF(B16<DATEVALUE("01/01/2050"),IF(SUMIFS(Precios!$V:$V,Precios!$E:$E,$C$8,Precios!$AP:$AP,"<="&$C$18,Precios!$AQ:$AQ,">="&$C$18)>=0,SUMIFS(Precios!$V:$V,Precios!$E:$E,$C$8,Precios!$AP:$AP,"<="&$C$18,Precios!$AQ:$AQ,">="&$C$18)),"NA") -> 14539 | K18: =IF(B16<DATEVALUE("01/01/2050"),IF(SUMIFS(Precios!$AA:$AA,Precios!$E:$E,$C$8,Precios!$AP:$AP,"<="&$C$18,Precios!$AQ:$AQ,">="&$C$18)>=0,SUMIFS(Precios!$AA:$AA,Precios!$E:$E,$C$8,Precios!$AP:$AP,"<="&$C$18,Precios!$AQ:$AQ,">="&$C$18)),"NA") -> 14229 | L18: =IF(B16<DATEVALUE("01/01/2050"),IF(SUMIFS(Precios!$AF:$AF,Precios!$E:$E,$C$8,Precios!$AP:$AP,"<="&$C$18,Precios!$AQ:$AQ,">="&$C$18)>=0,SUMIFS(Precios!$AF:$AF,Precios!$E:$E,$C$8,Precios!$AP:$AP,"<="&$C$18,Precios!$AQ:$AQ,">="&$C$18)),"NA") -> 13479 | M18: =IF(B16<DATEVALUE("01/01/2050"),IF(SUMIFS(Precios!$AK:$AK,Precios!$E:$E,$C$8,Precios!$AP:$AP,"<="&$C$18,Precios!$AQ:$AQ,">="&$C$18)>=0,SUMIFS(Precios!$AK:$AK,Precios!$E:$E,$C$8,Precios!$AP:$AP,"<="&$C$18,Precios!$AQ:$AQ,">="&$C$18)),"NA") -> 13169
B19: SIGUIENTE FIN VIGENCIA | C19: =IF(B20=DATEVALUE("01/01/2050"), "INDEFINIDO", B20) -> INDEFINIDO | F19: 18 Meses | G19: =IF(B16<DATEVALUE("01/01/2050"),IF(SUMIFS(Precios!$H:$H,Precios!$E:$E,$C$8,Precios!$AP:$AP,"<="&$C$18,Precios!$AQ:$AQ,">="&$C$18)>=0,SUMIFS(Precios!$H:$H,Precios!$E:$E,$C$8,Precios!$AP:$AP,"<="&$C$18,Precios!$AQ:$AQ,">="&$C$18)),"NA") -> 14759 | H19: =IF(B16<DATEVALUE("01/01/2050"),IF(SUMIFS(Precios!$M:$M,Precios!$E:$E,$C$8,Precios!$AP:$AP,"<="&$C$18,Precios!$AQ:$AQ,">="&$C$18)>=0,SUMIFS(Precios!$M:$M,Precios!$E:$E,$C$8,Precios!$AP:$AP,"<="&$C$18,Precios!$AQ:$AQ,">="&$C$18)),"NA") -> 14539 | I19: =IF(B16<DATEVALUE("01/01/2050"),IF(SUMIFS(Precios!$R:$R,Precios!$E:$E,$C$8,Precios!$AP:$AP,"<="&$C$18,Precios!$AQ:$AQ,">="&$C$18)>=0,SUMIFS(Precios!$R:$R,Precios!$E:$E,$C$8,Precios!$AP:$AP,"<="&$C$18,Precios!$AQ:$AQ,">="&$C$18)),"NA") -> 14309 | J19: =IF(B16<DATEVALUE("01/01/2050"),IF(SUMIFS(Precios!$W:$W,Precios!$E:$E,$C$8,Precios!$AP:$AP,"<="&$C$18,Precios!$AQ:$AQ,">="&$C$18)>=0,SUMIFS(Precios!$W:$W,Precios!$E:$E,$C$8,Precios!$AP:$AP,"<="&$C$18,Precios!$AQ:$AQ,">="&$C$18)),"NA") -> 14079 | K19: =IF(B16<DATEVALUE("01/01/2050"),IF(SUMIFS(Precios!$AB:$AB,Precios!$E:$E,$C$8,Precios!$AP:$AP,"<="&$C$18,Precios!$AQ:$AQ,">="&$C$18)>=0,SUMIFS(Precios!$AB:$AB,Precios!$E:$E,$C$8,Precios!$AP:$AP,"<="&$C$18,Precios!$AQ:$AQ,">="&$C$18)),"NA") -> 13629 | L19: =IF(B16<DATEVALUE("01/01/2050"),IF(SUMIFS(Precios!$AG:$AG,Precios!$E:$E,$C$8,Precios!$AP:$AP,"<="&$C$18,Precios!$AQ:$AQ,">="&$C$18)>=0,SUMIFS(Precios!$AG:$AG,Precios!$E:$E,$C$8,Precios!$AP:$AP,"<="&$C$18,Precios!$AQ:$AQ,">="&$C$18)),"NA") -> 12489 | M19: =IF(B16<DATEVALUE("01/01/2050"),IF(SUMIFS(Precios!$AL:$AL,Precios!$E:$E,$C$8,Precios!$AP:$AP,"<="&$C$18,Precios!$AQ:$AQ,">="&$C$18)>=0,SUMIFS(Precios!$AL:$AL,Precios!$E:$E,$C$8,Precios!$AP:$AP,"<="&$C$18,Precios!$AQ:$AQ,">="&$C$18)),"NA") -> 12039
B20: =IF(B16<=DATEVALUE("31/12/2026"),IF(SUMIFS(Precios!$AQ:$AQ,Precios!$E:$E,$C$8,Precios!$AP:$AP,"<="&$C$18,Precios!$AQ:$AQ,">="&$C$18)>=0,SUMIFS(Precios!$AQ:$AQ,Precios!$E:$E,$C$8,Precios!$AP:$AP,"<="&$C$18,Precios!$AQ:$AQ,">="&$C$18)),"NA") -> 54789 | F20: 24 Meses | G20: =IF(B16<DATEVALUE("01/01/2050"),IF(SUMIFS(Precios!$I:$I,Precios!$E:$E,$C$8,Precios!$AP:$AP,"<="&$C$18,Precios!$AQ:$AQ,">="&$C$18)>=0,SUMIFS(Precios!$I:$I,Precios!$E:$E,$C$8,Precios!$AP:$AP,"<="&$C$18,Precios!$AQ:$AQ,">="&$C$18)),"NA") -> 14539 | H20: =IF(B16<DATEVALUE("01/01/2050"),IF(SUMIFS(Precios!$N:$N,Precios!$E:$E,$C$8,Precios!$AP:$AP,"<="&$C$18,Precios!$AQ:$AQ,">="&$C$18)>=0,SUMIFS(Precios!$N:$N,Precios!$E:$E,$C$8,Precios!$AP:$AP,"<="&$C$18,Precios!$AQ:$AQ,">="&$C$18)),"NA") -> 14239 | I20: =IF(B16<DATEVALUE("01/01/2050"),IF(SUMIFS(Precios!$S:$S,Precios!$E:$E,$C$8,Precios!$AP:$AP,"<="&$C$18,Precios!$AQ:$AQ,">="&$C$18)>=0,SUMIFS(Precios!$S:$S,Precios!$E:$E,$C$8,Precios!$AP:$AP,"<="&$C$18,Precios!$AQ:$AQ,">="&$C$18)),"NA") -> 13929 | J20: =IF(B16<DATEVALUE("01/01/2050"),IF(SUMIFS(Precios!$X:$X,Precios!$E:$E,$C$8,Precios!$AP:$AP,"<="&$C$18,Precios!$AQ:$AQ,">="&$C$18)>=0,SUMIFS(Precios!$X:$X,Precios!$E:$E,$C$8,Precios!$AP:$AP,"<="&$C$18,Precios!$AQ:$AQ,">="&$C$18)),"NA") -> 13629 | K20: =IF(B16<DATEVALUE("01/01/2050"),IF(SUMIFS(Precios!$AC:$AC,Precios!$E:$E,$C$8,Precios!$AP:$AP,"<="&$C$18,Precios!$AQ:$AQ,">="&$C$18)>=0,SUMIFS(Precios!$AC:$AC,Precios!$E:$E,$C$8,Precios!$AP:$AP,"<="&$C$18,Precios!$AQ:$AQ,">="&$C$18)),"NA") -> 13019 | L20: =IF(B16<DATEVALUE("01/01/2050"),IF(SUMIFS(Precios!$AH:$AH,Precios!$E:$E,$C$8,Precios!$AP:$AP,"<="&$C$18,Precios!$AQ:$AQ,">="&$C$18)>=0,SUMIFS(Precios!$AH:$AH,Precios!$E:$E,$C$8,Precios!$AP:$AP,"<="&$C$18,Precios!$AQ:$AQ,">="&$C$18)),"NA") -> 11509 | M20: =IF(B16<DATEVALUE("01/01/2050"),IF(SUMIFS(Precios!$AM:$AM,Precios!$E:$E,$C$8,Precios!$AP:$AP,"<="&$C$18,Precios!$AQ:$AQ,">="&$C$18)>=0,SUMIFS(Precios!$AM:$AM,Precios!$E:$E,$C$8,Precios!$AP:$AP,"<="&$C$18,Precios!$AQ:$AQ,">="&$C$18)),"NA") -> 10899
F21: 36 Meses | G21: =IF(B16<DATEVALUE("01/01/2050"),IF(SUMIFS(Precios!$J:$J,Precios!$E:$E,$C$8,Precios!$AP:$AP,"<="&$C$18,Precios!$AQ:$AQ,">="&$C$18)>=0,SUMIFS(Precios!$J:$J,Precios!$E:$E,$C$8,Precios!$AP:$AP,"<="&$C$18,Precios!$AQ:$AQ,">="&$C$18)),"NA") -> 14089 | H21: =IF(B16<DATEVALUE("01/01/2050"),IF(SUMIFS(Precios!$O:$O,Precios!$E:$E,$C$8,Precios!$AP:$AP,"<="&$C$18,Precios!$AQ:$AQ,">="&$C$18)>=0,SUMIFS(Precios!$O:$O,Precios!$E:$E,$C$8,Precios!$AP:$AP,"<="&$C$18,Precios!$AQ:$AQ,">="&$C$18)),"NA") -> 13629 | I21: =IF(B16<DATEVALUE("01/01/2050"),IF(SUMIFS(Precios!$T:$T,Precios!$E:$E,$C$8,Precios!$AP:$AP,"<="&$C$18,Precios!$AQ:$AQ,">="&$C$18)>=0,SUMIFS(Precios!$T:$T,Precios!$E:$E,$C$8,Precios!$AP:$AP,"<="&$C$18,Precios!$AQ:$AQ,">="&$C$18)),"NA") -> 13179 | J21: =IF(B16<DATEVALUE("01/01/2050"),IF(SUMIFS(Precios!$Y:$Y,Precios!$E:$E,$C$8,Precios!$AP:$AP,"<="&$C$18,Precios!$AQ:$AQ,">="&$C$18)>=0,SUMIFS(Precios!$Y:$Y,Precios!$E:$E,$C$8,Precios!$AP:$AP,"<="&$C$18,Precios!$AQ:$AQ,">="&$C$18)),"NA") -> 12719 | K21: =IF(B16<DATEVALUE("01/01/2050"),IF(SUMIFS(Precios!$AD:$AD,Precios!$E:$E,$C$8,Precios!$AP:$AP,"<="&$C$18,Precios!$AQ:$AQ,">="&$C$18)>=0,SUMIFS(Precios!$AD:$AD,Precios!$E:$E,$C$8,Precios!$AP:$AP,"<="&$C$18,Precios!$AQ:$AQ,">="&$C$18)),"NA") -> 11809 | L21: =IF(B16<DATEVALUE("01/01/2050"),IF(SUMIFS(Precios!$AI:$AI,Precios!$E:$E,$C$8,Precios!$AP:$AP,"<="&$C$18,Precios!$AQ:$AQ,">="&$C$18)>=0,SUMIFS(Precios!$AI:$AI,Precios!$E:$E,$C$8,Precios!$AP:$AP,"<="&$C$18,Precios!$AQ:$AQ,">="&$C$18)),"NA") -> 9539 | M21: =IF(B16<DATEVALUE("01/01/2050"),IF(SUMIFS(Precios!$AN:$AN,Precios!$E:$E,$C$8,Precios!$AP:$AP,"<="&$C$18,Precios!$AQ:$AQ,">="&$C$18)>=0,SUMIFS(Precios!$AN:$AN,Precios!$E:$E,$C$8,Precios!$AP:$AP,"<="&$C$18,Precios!$AQ:$AQ,">="&$C$18)),"NA") -> 8629
F22: 48 Meses | G22: =IF(B16<DATEVALUE("01/01/2050"),IF(SUMIFS(Precios!$K:$K,Precios!$E:$E,$C$8,Precios!$AP:$AP,"<="&$C$18,Precios!$AQ:$AQ,">="&$C$18)>=0,SUMIFS(Precios!$K:$K,Precios!$E:$E,$C$8,Precios!$AP:$AP,"<="&$C$18,Precios!$AQ:$AQ,">="&$C$18)),"NA") -> 13629 | H22: =IF(B16<DATEVALUE("01/01/2050"),IF(SUMIFS(Precios!$P:$P,Precios!$E:$E,$C$8,Precios!$AP:$AP,"<="&$C$18,Precios!$AQ:$AQ,">="&$C$18)>=0,SUMIFS(Precios!$P:$P,Precios!$E:$E,$C$8,Precios!$AP:$AP,"<="&$C$18,Precios!$AQ:$AQ,">="&$C$18)),"NA") -> 13029 | I22: =IF(B16<DATEVALUE("01/01/2050"),IF(SUMIFS(Precios!$U:$U,Precios!$E:$E,$C$8,Precios!$AP:$AP,"<="&$C$18,Precios!$AQ:$AQ,">="&$C$18)>=0,SUMIFS(Precios!$U:$U,Precios!$E:$E,$C$8,Precios!$AP:$AP,"<="&$C$18,Precios!$AQ:$AQ,">="&$C$18)),"NA") -> 12419 | J22: =IF(B16<DATEVALUE("01/01/2050"),IF(SUMIFS(Precios!$Z:$Z,Precios!$E:$E,$C$8,Precios!$AP:$AP,"<="&$C$18,Precios!$AQ:$AQ,">="&$C$18)>=0,SUMIFS(Precios!$Z:$Z,Precios!$E:$E,$C$8,Precios!$AP:$AP,"<="&$C$18,Precios!$AQ:$AQ,">="&$C$18)),"NA") -> 11819 | K22: =IF(B16<DATEVALUE("01/01/2050"),IF(SUMIFS(Precios!$AE:$AE,Precios!$E:$E,$C$8,Precios!$AP:$AP,"<="&$C$18,Precios!$AQ:$AQ,">="&$C$18)>=0,SUMIFS(Precios!$AE:$AE,Precios!$E:$E,$C$8,Precios!$AP:$AP,"<="&$C$18,Precios!$AQ:$AQ,">="&$C$18)),"NA") -> 10599 | L22: =IF(B16<DATEVALUE("01/01/2050"),IF(SUMIFS(Precios!$AJ:$AJ,Precios!$E:$E,$C$8,Precios!$AP:$AP,"<="&$C$18,Precios!$AQ:$AQ,">="&$C$18)>=0,SUMIFS(Precios!$AJ:$AJ,Precios!$E:$E,$C$8,Precios!$AP:$AP,"<="&$C$18,Precios!$AQ:$AQ,">="&$C$18)),"NA") -> 7569 | M22: =IF(B16<DATEVALUE("01/01/2050"),IF(SUMIFS(Precios!$AO:$AO,Precios!$E:$E,$C$8,Precios!$AP:$AP,"<="&$C$18,Precios!$AQ:$AQ,">="&$C$18)>=0,SUMIFS(Precios!$AO:$AO,Precios!$E:$E,$C$8,Precios!$AP:$AP,"<="&$C$18,Precios!$AQ:$AQ,">="&$C$18)),"NA") -> 6359
B23: * Favor de considerar que para los equipos de la marca Samsung, se deberan consultar el "Inventario Simplificado Empresarial" en Insider para conocer las vigencia de los rebates.
B24: * El objetivo del cotizador, es mostrar los precios y vigencias actuales "como referencia".
B25: * La lista de precios se actualizará semanalmente, por lo que les pedimos revisar el archivo más actual.
B26: * Esta información no sustituye a los precios oficiales indicados en AVS, Digital y Sales Force (Modelador).
B27: * Si se requiere más detalle de los precios, favor de consultar las pestañas subsecuentes.
B28: * En el caso de los planes 199, 239, 699, 899 y 999, se debera considerar el precio de lista.

Sheet AT&T Armalo Neg 2.0
AW1: =UPPER(TEXT(AU1, " dd \ mmmm \ aa")&" - "&TEXT(AV1, " dd \ mmmm \ aa")) -> 00 ENERO 00 - 00 ENERO 00
F5: AT&T Armalo Negocios | L5: Ármalo Negocios 299 | Q5: Ármalo Negocios 399 | V5: Ármalo Negocios 499 | AA5: Ármalo Negocios 599 | AF5: Ármalo Negocios 799 | AK5: Ármalo Negocios 1299 | AP5: Ármalo Negocios 1499
A6: SAP | B6: Portal | C6: SKU | D6: Marca | E6: Nombre Completo | F6: Modelo | G6: Familia Homologada | H6: Tier | I6: Operador | J6: Precio Lista Sn/IVA | K6: Precio Lista Con IVA2 | L6: 12 Meses3 | M6: 18 Meses4 | N6: 24 Meses6 | O6: 36 Meses7 | P6: 48 Meses8 | Q6: 12 Meses22 | R6: 18 Meses33 | S6: 24 Meses44 | T6: 36 Meses55 | U6: 48 Meses66 | V6: 12 Meses23 | W6: 18 Meses34 | X6: 24 Meses45 | Y6: 36 Meses56 | Z6: 48 Meses67 | AA6: 12 Meses24 | AB6: 18 Meses35 | AC6: 24 Meses46 | AD6: 36 Meses57 | AE6: 48 Meses68 | AF6: 12 Meses26 | AG6: 18 Meses37 | AH6: 24 Meses48 | AI6: 36 Meses59 | AJ6: 48 Meses610 | AK6: 12 Meses272 | AL6: 18 Meses383 | AM6: 24 Meses494 | AN6: 36 Meses5105 | AO6: 48 Meses6116 | AP6: 12 Meses287 | AQ6: 18 Meses398 | AR6: 24 Meses4109 | AS6: 36 Meses51110 | AT6: 48 Meses61211 | AU6: Fecha Inicio | AV6: Fecha Fin | AW6: VIGENCIA
A7: 93523 | B7: 00935230 | C7: N.IP1164BL | D7: APPLE | E7: APPLE IPHONE 11 64GB BLANCO ATT | F7: Apple iPhone 11 64GB | G7: APPLE IPHONE 11 64GB 4G | H7: HIGH | I7: AT&T | J7: =K7/1.16 -> 9481.8966 | K7: 10999 | L7: 3849 | M7: 3499 | N7: 3149 | O7: 2499 | P7: 1799 | Q7: 3649 | R7: 3149 | S7: 2699 | T7: 1799 | U7: 899 | V7: 3399 | W7: 2849 | X7: 2249 | Y7: 1099 | Z7: 0 | AA7: 3149 | AB7: 2499 | AC7: 1799 | AD7: 449 | AE7: 0 | AF7: 2699 | AG7: 1799 | AH7: 899 | AI7: 0 | AJ7: 0 | AK7: 1549 | AL7: 99 | AM7: 0 | AN7: 0 | AO7: 0 | AP7: 1099 | AQ7: 0 | AR7: 0 | AS7: 0 | AT7: 0 | AU7: 46059 | AV7: INDEFINIDO | AW7: =UPPER(TEXT(AU7, " dd \ mmmm \ aa")&" - "&TEXT(AV7, " dd \ mmmm \ aa")) -> 06 FEBRERO 26 - INDEFINIDO
A8: 93526 | B8: 00935260 | C8: N.IP1164RJ | D8: APPLE | E8: APPLE IPHONE 11 64GB ROJO ATT | F8: Apple iPhone 11 64GB | G8: APPLE IPHONE 11 64GB 4G | H8: HIGH | I8: AT&T | J8: =K8/1.16 -> 9481.8966 | K8: 10999 | L8: 3849 | M8: 3499 | N8: 3149 | O8: 2499 | P8: 1799 | Q8: 3649 | R8: 3149 | S8: 2699 | T8: 1799 | U8: 899 | V8: 3399 | W8: 2849 | X8: 2249 | Y8: 1099 | Z8: 0 | AA8: 3149 | AB8: 2499 | AC8: 1799 | AD8: 449 | AE8: 0 | AF8: 2699 | AG8: 1799 | AH8: 899 | AI8: 0 | AJ8: 0 | AK8: 1549 | AL8: 99 | AM8: 0 | AN8: 0 | AO8: 0 | AP8: 1099 | AQ8: 0 | AR8: 0 | AS8: 0 | AT8: 0 | AU8: 46059 | AV8: INDEFINIDO | AW8: =UPPER(TEXT(AU8, " dd \ mmmm \ aa")&" - "&TEXT(AV8, " dd \ mmmm \ aa")) -> 06 FEBRERO 26 - INDEFINIDO
A9: 93520 | B9: 00935200 | C9: N.IP1164NG | D9: APPLE | E9: APPLE IPHONE 11 64GB NEGRO ATT | F9: Apple iPhone 11 64GB | G9: APPLE IPHONE 11 64GB 4G | H9: HIGH | I9: AT&T | J9: =K9/1.16 -> 9481.8966 | K9: 10999 | L9: 3849 | M9: 3499 | N9: 3149 | O9: 2499 | P9: 1799 | Q9: 3649 | R9: 3149 | S9: 2699 | T9: 1799 | U9: 899 | V9: 3399 | W9: 2849 | X9: 2249 | Y9: 1099 | Z9: 0 | AA9: 3149 | AB9: 2499 | AC9: 1799 | AD9: 449 | AE9: 0 | AF9: 2699 | AG9: 1799 | AH9: 899 | AI9: 0 | AJ9: 0 | AK9: 1549 | AL9: 99 | AM9: 0 | AN9: 0 | AO9: 0 | AP9: 1099 | AQ9: 0 | AR9: 0 | AS9: 0 | AT9: 0 | AU9: 46059 | AV9: INDEFINIDO | AW9: =UPPER(TEXT(AU9, " dd \ mmmm \ aa")&" - "&TEXT(AV9, " dd \ mmmm \ aa")) -> 06 FEBRERO 26 - INDEFINIDO
A10: 95520 | B10: 00955200 | C10: N.I1164LB | D10: APPLE | E10: APPLE IPHONE 11 64GB BLANCO CON CABLE DE LIGHTNING A U﻿S﻿B﻿-﻿C ATT | F10: Apple iPhone 11 64GB | G10: APPLE IPHONE 11 64GB 4G | H10: HIGH | I10: AT&T | J10: =K10/1.16 -> 9481.8966 | K10: 10999 | L10: 3849 | M10: 3499 | N10: 3149 | O10: 2499 | P10: 1799 | Q10: 3649 | R10: 3149 | S10: 2699 | T10: 1799 | U10: 899 | V10: 3399 | W10: 2849 | X10: 2249 | Y10: 1099 | Z10: 0 | AA10: 3149 | AB10: 2499 | AC10: 1799 | AD10: 449 | AE10: 0 | AF10: 2699 | AG10: 1799 | AH10: 899 | AI10: 0 | AJ10: 0 | AK10: 1549 | AL10: 99 | AM10: 0 | AN10: 0 | AO10: 0 | AP10: 1099 | AQ10: 0 | AR10: 0 | AS10: 0 | AT10: 0 | AU10: 46059 | AV10: INDEFINIDO | AW10: =UPPER(TEXT(AU10, " dd \ mmmm \ aa")&" - "&TEXT(AV10, " dd \ mmmm \ aa")) -> 06 FEBRERO 26 - INDEFINIDO
A11: 95524 | B11: 00955240 | C11: N.I1164LR | D11: APPLE | E11: APPLE IPHONE 11 64GB ROJO CON CABLE DE LIGHTNING A U﻿S﻿B﻿-﻿C ATT | F11: Apple iPhone 11 64GB | G11: APPLE IPHONE 11 64GB 4G | H11: HIGH | I11: AT&T | J11: =K11/1.16 -> 9481.8966 | K11: 10999 | L11: 3849 | M11: 3499 | N11: 3149 | O11: 2499 | P11: 1799 | Q11: 3649 | R11: 3149 | S11: 2699 | T11: 1799 | U11: 899 | V11: 3399 | W11: 2849 | X11: 2249 | Y11: 1099 | Z11: 0 | AA11: 3149 | AB11: 2499 | AC11: 1799 | AD11: 449 | AE11: 0 | AF11: 2699 | AG11: 1799 | AH11: 899 | AI11: 0 | AJ11: 0 | AK11: 1549 | AL11: 99 | AM11: 0 | AN11: 0 | AO11: 0 | AP11: 1099 | AQ11: 0 | AR11: 0 | AS11: 0 | AT11: 0 | AU11: 46059 | AV11: INDEFINIDO | AW11: =UPPER(TEXT(AU11, " dd \ mmmm \ aa")&" - "&TEXT(AV11, " dd \ mmmm \ aa")) -> 06 FEBRERO 26 - INDEFINIDO
A12: 95516 | B12: 00955160 | C12: N.I1164LN | D12: APPLE | E12: APPLE IPHONE 11 64GB NEGRO CON CABLE DE LIGHTNING A U﻿S﻿B﻿-﻿C ATT | F12: Apple iPhone 11 64GB | G12: APPLE IPHONE 11 64GB 4G | H12: =IF(K12="REVISAR","REVISAR",IF(K12>=20000,"FLAGSHIP",IF(K12>=12000,"PREMIUM",IF(K12>=7000,"HIGH",IF(K12>=5000,"MID",IF(K12>=3000,"LOW","ENTRY")))))) -> HIGH | I12: AT&T | J12: =K12/1.16 -> 9481.8966 | K12: 10999 | L12: 3849 | M12: 3499 | N12: 3149 | O12: 2499 | P12: 1799 | Q12: 3649 | R12: 3149 | S12: 2699 | T12: 1799 | U12: 899 | V12: 3399 | W12: 2849 | X12: 2249 | Y12: 1099 | Z12: 0 | AA12: 3149 | AB12: 2499 | AC12: 1799 | AD12: 449 | AE12: 0 | AF12: 2699 | AG12: 1799 | AH12: 899 | AI12: 0 | AJ12: 0 | AK12: 1549 | AL12: 99 | AM12: 0 | AN12: 0 | AO12: 0 | AP12: 1099 | AQ12: 0 | AR12: 0 | AS12: 0 | AT12: 0 | AU12: 46059 | AV12: INDEFINIDO | AW12: =UPPER(TEXT(AU12, " dd \ mmmm \ aa")&" - "&TEXT(AV12, " dd \ mmmm \ aa")) -> 06 FEBRERO 26 - INDEFINIDO
A13: 95316 | B13: 95316 | C13: N.IP1264AZ | D13: APPLE | E13: APPLE IPHONE 12 64GB AZUL ATT | F13: Apple iPhone 12 64GB | G13: APPLE IPHONE 12 64GB 4G | H13: PREMIUM | I13: AT&T | J13: =K13/1.16 -> 10775 | K13: 12499 | L13: 10899 | M13: 10699 | N13: 10499 | O13: 9999 | P13: 9599 | Q13: 10799 | R13: 10499 | S13: 10199 | T13: 9599 | U13: 8999 | V13: 10599 | W13: 10199 | X13: 9899 | Y13: 9099 | Z13: 8399 | AA13: 10499 | AB13: 9999 | AC13: 9599 | AD13: 8699 | AE13: 7799 | AF13: 10199 | AG13: 9599 | AH13: 8999 | AI13: 7799 | AJ13: 6599 | AK13: 9399 | AL13: 8399 | AM13: 7499 | AN13: 5499 | AO13: 3599 | AP13: 9099 | AQ13: 7999 | AR13: 6899 | AS13: 4599 | AT13: 2399 | AU13: 45505 | AV13: INDEFINIDO | AW13: 01 Agosto 2024 - INDEFINIDO
A14: 95304 | B14: 95304 | C14: N.IP1264BL | D14: APPLE | E14: APPLE IPHONE 12 64GB BLANCO ATT | F14: Apple iPhone 12 64GB | G14: APPLE IPHONE 12 64GB 4G | H14: PREMIUM | I14: AT&T | J14: =K14/1.16 -> 10775 | K14: 12499 | L14: 10899 | M14: 10699 | N14: 10499 | O14: 9999 | P14: 9599 | Q14: 10799 | R14: 10499 | S14: 10199 | T14: 9599 | U14: 8999 | V14: 10599 | W14: 10199 | X14: 9899 | Y14: 9099 | Z14: 8399 | AA14: 10499 | AB14: 9999 | AC14: 9599 | AD14: 8699 | AE14: 7799 | AF14: 10199 | AG14: 9599 | AH14: 8999 | AI14: 7799 | AJ14: 6599 | AK14: 9399 | AL14: 8399 | AM14: 7499 | AN14: 5499 | AO14: 3599 | AP14: 9099 | AQ14: 7999 | AR14: 6899 | AS14: 4599 | AT14: 2399 | AU14: 45505 | AV14: INDEFINIDO | AW14: 01 Agosto 2024 - INDEFINIDO
A15: 96152 | B15: 96152 | C15: N.IP1264MD | D15: APPLE | E15: APPLE IPHONE 12 64GB MORADO ATT | F15: Apple iPhone 12 64GB | G15: APPLE IPHONE 12 64GB 4G | H15: PREMIUM | I15: AT&T | J15: =K15/1.16 -> 10775 | K15: 12499 | L15: 10899 | M15: 10699 | N15: 10499 | O15: 9999 | P15: 9599 | Q15: 10799 | R15: 10499 | S15: 10199 | T15: 9599 | U15: 8999 | V15: 10599 | W15: 10199 | X15: 9899 | Y15: 9099 | Z15: 8399 | AA15: 10499 | AB15: 9999 | AC15: 9599 | AD15: 8699 | AE15: 7799 | AF15: 10199 | AG15: 9599 | AH15: 8999 | AI15: 7799 | AJ15: 6599 | AK15: 9399 | AL15: 8399 | AM15: 7499 | AN15: 5499 | AO15: 3599 | AP15: 9099 | AQ15: 7999 | AR15: 6899 | AS15: 4599 | AT15: 2399 | AU15: 45505 | AV15: INDEFINIDO | AW15: 01 Agosto 2024 - INDEFINIDO
A16: 95300 | B16: 95300 | C16: N.IP1264NG | D16: APPLE | E16: APPLE IPHONE 12 64GB NEGRO ATT | F16: Apple iPhone 12 64GB | G16: APPLE IPHONE 12 64GB 4G | H16: PREMIUM | I16: AT&T | J16: =K16/1.16 -> 10775 | K16: 12499 | L16: 10899 | M16: 10699 | N16: 10499 | O16: 9999 | P16: 9599 | Q16: 10799 | R16: 10499 | S16: 10199 | T16: 9599 | U16: 8999 | V16: 10599 | W16: 10199 | X16: 9899 | Y16: 9099 | Z16: 8399 | AA16: 10499 | AB16: 9999 | AC16: 9599 | AD16: 8699 | AE16: 7799 | AF16: 10199 | AG16: 9599 | AH16: 8999 | AI16: 7799 | AJ16: 6599 | AK16: 9399 | AL16: 8399 | AM16: 7499 | AN16: 5499 | AO16: 3599 | AP16: 9099 | AQ16: 7999 | AR16: 6899 | AS16: 4599 | AT16: 2399 | AU16: 45505 | AV16: INDEFINIDO | AW16: 01 Agosto 2024 - INDEFINIDO
A17: 95308 | B17: 95308 | C17: N.IP1264RJ | D17: APPLE | E17: APPLE IPHONE 12 64GB ROJO ATT | F17: Apple iPhone 12 64GB | G17: APPLE IPHONE 12 64GB 4G | H17: PREMIUM | I17: AT&T | J17: =K17/1.16 -> 10775 | K17: 12499 | L17: 10899 | M17: 10699 | N17: 10499 | O17: 9999 | P17: 9599 | Q17: 10799 | R17: 10499 | S17: 10199 | T17: 9599 | U17: 8999 | V17: 10599 | W17: 10199 | X17: 9899 | Y17: 9099 | Z17: 8399 | AA17: 10499 | AB17: 9999 | AC17: 9599 | AD17: 8699 | AE17: 7799 | AF17: 10199 | AG17: 9599 | AH17: 8999 | AI17: 7799 | AJ17: 6599 | AK17: 9399 | AL17: 8399 | AM17: 7499 | AN17: 5499 | AO17: 3599 | AP17: 9099 | AQ17: 7999 | AR17: 6899 | AS17: 4599 | AT17: 2399 | AU17: 45505 | AV17: INDEFINIDO | AW17: 01 Agosto 2024 - INDEFINIDO
A18: 95312 | B18: 95312 | C18: N.IP1264VD | D18: APPLE | E18: APPLE IPHONE 12 64GB VERDE ATT | F18: Apple iPhone 12 64GB | G18: APPLE IPHONE 12 64GB 4G | H18: PREMIUM | I18: AT&T | J18: =K18/1.16 -> 10775 | K18: 12499 | L18: 10899 | M18: 10699 | N18: 10499 | O18: 9999 | P18: 9599 | Q18: 10799 | R18: 10499 | S18: 10199 | T18: 9599 | U18: 8999 | V18: 10599 | W18: 10199 | X18: 9899 | Y18: 9099 | Z18: 8399 | AA18: 10499 | AB18: 9999 | AC18: 9599 | AD18: 8699 | AE18: 7799 | AF18: 10199 | AG18: 9599 | AH18: 8999 | AI18: 7799 | AJ18: 6599 | AK18: 9399 | AL18: 8399 | AM18: 7499 | AN18: 5499 | AO18: 3599 | AP18: 9099 | AQ18: 7999 | AR18: 6899 | AS18: 4599 | AT18: 2399 | AU18: 45505 | AV18: INDEFINIDO | AW18: 01 Agosto 2024 - INDEFINIDO
A19: 96603 | B19: 00966030 | C19: N.I13128PA | D19: APPLE | E19: APPLE IPHONE 13 128GB AZUL ATT | F19: Apple iPhone 13 128GB | G19: APPLE IPHONE 13 128GB 4G | H19: =IF(K19="REVISAR","REVISAR",IF(K19>=20000,"FLAGSHIP",IF(K19>=12000,"PREMIUM",IF(K19>=7000,"HIGH",IF(K19>=5000,"MID",IF(K19>=3000,"LOW","ENTRY")))))) -> PREMIUM | I19: AT&T | J19: =K19/1.16 -> 11206.034 | K19: 12999 | L19: 9099 | M19: 8749 | N19: 8399 | O19: 7699 | P19: 7049 | Q19: 8849 | R19: 8399 | S19: 7949 | T19: 7049 | U19: 6149 | V19: 8649 | W19: 8049 | X19: 7499 | Y19: 6349 | Z19: 5199 | AA19: 8399 | AB19: 7699 | AC19: 7049 | AD19: 5649 | AE19: 4299 | AF19: 7949 | AG19: 7049 | AH19: 6099 | AI19: 4299 | AJ19: 2499 | AK19: 6799 | AL19: 5299 | AM19: 3849 | AN19: 899 | AO19: 0 | AP19: 6349 | AQ19: 4649 | AR19: 2949 | AS19: 0 | AT19: 0 | AU19: 46110 | AV19: INDEFINIDO | AW19: =UPPER(TEXT(AU19, " dd \ mmmm \ aa")&" - "&TEXT(AV19, " dd \ mmmm \ aa")) -> 29 MARZO 26 - INDEFINIDO
A20: 96599 | B20: 00965990 | C20: N.I13128PR | D20: APPLE | E20: APPLE IPHONE 13 128GB ROJO ATT | F20: Apple iPhone 13 128GB | G20: APPLE IPHONE 13 128GB 4G | H20: =IF(K20="REVISAR","REVISAR",IF(K20>=20000,"FLAGSHIP",IF(K20>=12000,"PREMIUM",IF(K20>=7000,"HIGH",IF(K20>=5000,"MID",IF(K20>=3000,"LOW","ENTRY")))))) -> PREMIUM | I20: AT&T | J20: =K20/1.16 -> 11206.034 | K20: 12999 | L20: 9099 | M20: 8749 | N20: 8399 | O20: 7699 | P20: 7049 | Q20: 8849 | R20: 8399 | S20: 7949 | T20: 7049 | U20: 6149 | V20: 8649 | W20: 8049 | X20: 7499 | Y20: 6349 | Z20: 5199 | AA20: 8399 | AB20: 7699 | AC20: 7049 | AD20: 5649 | AE20: 4299 | AF20: 7949 | AG20: 7049 | AH20: 6099 | AI20: 4299 | AJ20: 2499 | AK20: 6799 | AL20: 5299 | AM20: 3849 | AN20: 899 | AO20: 0 | AP20: 6349 | AQ20: 4649 | AR20: 2949 | AS20: 0 | AT20: 0 | AU20: 46110 | AV20: INDEFINIDO | AW20: =UPPER(TEXT(AU20, " dd \ mmmm \ aa")&" - "&TEXT(AV20, " dd \ mmmm \ aa")) -> 29 MARZO 26 - INDEFINIDO
A21: 96595 | B21: 00965950 | C21: N.I13128PS | D21: APPLE | E21: APPLE IPHONE 13 128GB ROSA ATT | F21: Apple iPhone 13 128GB | G21: APPLE IPHONE 13 128GB 4G | H21: =IF(K21="REVISAR","REVISAR",IF(K21>=20000,"FLAGSHIP",IF(K21>=12000,"PREMIUM",IF(K21>=7000,"HIGH",IF(K21>=5000,"MID",IF(K21>=3000,"LOW","ENTRY")))))) -> PREMIUM | I21: AT&T | J21: =K21/1.16 -> 11206.034 | K21: 12999 | L21: 9099 | M21: 8749 | N21: 8399 | O21: 7699 | P21: 7049 | Q21: 8849 | R21: 8399 | S21: 7949 | T21: 7049 | U21: 6149 | V21: 8649 | W21: 8049 | X21: 7499 | Y21: 6349 | Z21: 5199 | AA21: 8399 | AB21: 7699 | AC21: 7049 | AD21: 5649 | AE21: 4299 | AF21: 7949 | AG21: 7049 | AH21: 6099 | AI21: 4299 | AJ21: 2499 | AK21: 6799 | AL21: 5299 | AM21: 3849 | AN21: 899 | AO21: 0 | AP21: 6349 | AQ21: 4649 | AR21: 2949 | AS21: 0 | AT21: 0 | AU21: 46110 | AV21: INDEFINIDO | AW21: =UPPER(TEXT(AU21, " dd \ mmmm \ aa")&" - "&TEXT(AV21, " dd \ mmmm \ aa")) -> 29 MARZO 26 - INDEFINIDO
A22: 97658 | B22: 00976580 | C22: N.I13128PV | D22: APPLE | E22: APPLE IPHONE 13 128GB VERDE ATT | F22: Apple iPhone 13 128GB | G22: APPLE IPHONE 13 128GB 4G | H22: =IF(K22="REVISAR","REVISAR",IF(K22>=20000,"FLAGSHIP",IF(K22>=12000,"PREMIUM",IF(K22>=7000,"HIGH",IF(K22>=5000,"MID",IF(K22>=3000,"LOW","ENTRY")))))) -> PREMIUM | I22: AT&T | J22: =K22/1.16 -> 11206.034 | K22: 12999 | L22: 9099 | M22: 8749 | N22: 8399 | O22: 7699 | P22: 7049 | Q22: 8849 | R22: 8399 | S22: 7949 | T22: 7049 | U22: 6149 | V22: 8649 | W22: 8049 | X22: 7499 | Y22: 6349 | Z22: 5199 | AA22: 8399 | AB22: 7699 | AC22: 7049 | AD22: 5649 | AE22: 4299 | AF22: 7949 | AG22: 7049 | AH22: 6099 | AI22: 4299 | AJ22: 2499 | AK22: 6799 | AL22: 5299 | AM22: 3849 | AN22: 899 | AO22: 0 | AP22: 6349 | AQ22: 4649 | AR22: 2949 | AS22: 0 | AT22: 0 | AU22: 46110 | AV22: INDEFINIDO | AW22: =UPPER(TEXT(AU22, " dd \ mmmm \ aa")&" - "&TEXT(AV22, " dd \ mmmm \ aa")) -> 29 MARZO 26 - INDEFINIDO
A23: 96591 | B23: 00965910 | C23: N.I13128PB | D23: APPLE | E23: APPLE IPHONE 13 128GB BLANCO ESTRELLA ATT | F23: Apple iPhone 13 128GB | G23: APPLE IPHONE 13 128GB 4G | H23: =IF(K23="REVISAR","REVISAR",IF(K23>=20000,"FLAGSHIP",IF(K23>=12000,"PREMIUM",IF(K23>=7000,"HIGH",IF(K23>=5000,"MID",IF(K23>=3000,"LOW","ENTRY")))))) -> PREMIUM | I23: AT&T | J23: =K23/1.16 -> 11206.034 | K23: 12999 | L23: 9099 | M23: 8749 | N23: 8399 | O23: 7699 | P23: 7049 | Q23: 8849 | R23: 8399 | S23: 7949 | T23: 7049 | U23: 6149 | V23: 8649 | W23: 8049 | X23: 7499 | Y23: 6349 | Z23: 5199 | AA23: 8399 | AB23: 7699 | AC23: 7049 | AD23: 5649 | AE23: 4299 | AF23: 7949 | AG23: 7049 | AH23: 6099 | AI23: 4299 | AJ23: 2499 | AK23: 6799 | AL23: 5299 | AM23: 3849 | AN23: 899 | AO23: 0 | AP23: 6349 | AQ23: 4649 | AR23: 2949 | AS23: 0 | AT23: 0 | AU23: 46110 | AV23: INDEFINIDO | AW23: =UPPER(TEXT(AU23, " dd \ mmmm \ aa")&" - "&TEXT(AV23, " dd \ mmmm \ aa")) -> 29 MARZO 26 - INDEFINIDO
A24: 96587 | B24: 00965870 | C24: N.I13128PN | D24: APPLE | E24: APPLE IPHONE 13 128GB MEDIA NOCHE ATT | F24: Apple iPhone 13 128GB | G24: APPLE IPHONE 13 128GB 4G | H24: =IF(K24="REVISAR","REVISAR",IF(K24>=20000,"FLAGSHIP",IF(K24>=12000,"PREMIUM",IF(K24>=7000,"HIGH",IF(K24>=5000,"MID",IF(K24>=3000,"LOW","ENTRY")))))) -> PREMIUM | I24: AT&T | J24: =K24/1.16 -> 11206.034 | K24: 12999 | L24: 9099 | M24: 8749 | N24: 8399 | O24: 7699 | P24: 7049 | Q24: 8849 | R24: 8399 | S24: 7949 | T24: 7049 | U24: 6149 | V24: 8649 | W24: 8049 | X24: 7499 | Y24: 6349 | Z24: 5199 | AA24: 8399 | AB24: 7699 | AC24: 7049 | AD24: 5649 | AE24: 4299 | AF24: 7949 | AG24: 7049 | AH24: 6099 | AI24: 4299 | AJ24: 2499 | AK24: 6799 | AL24: 5299 | AM24: 3849 | AN24: 899 | AO24: 0 | AP24: 6349 | AQ24: 4649 | AR24: 2949 | AS24: 0 | AT24: 0 | AU24: 46110 | AV24: INDEFINIDO | AW24: =UPPER(TEXT(AU24, " dd \ mmmm \ aa")&" - "&TEXT(AV24, " dd \ mmmm \ aa")) -> 29 MARZO 26 - INDEFINIDO
A25: 99420 | B25: 00994200 | C25: N.I14128AM | D25: APPLE | E25: IPHONE 14 128GB AMARILLO ATT | F25: Apple iPhone 14 128GB | G25: APPLE IPHONE 14 128GB 4G | H25: =IF(K25="REVISAR","REVISAR",IF(K25>=20000,"FLAGSHIP",IF(K25>=12000,"PREMIUM",IF(K25>=7000,"HIGH",IF(K25>=5000,"MID",IF(K25>=3000,"LOW","ENTRY")))))) -> PREMIUM | I25: AT&T | J25: =K25/1.16 -> 12930.172 | K25: 14999 | L25: 10849 | M25: 10599 | N25: 10399 | O25: 9949 | P25: 9499 | Q25: 10699 | R25: 10399 | S25: 10099 | T25: 9499 | U25: 8949 | V25: 10549 | W25: 10149 | X25: 9799 | Y25: 9099 | Z25: 8349 | AA25: 10399 | AB25: 9949 | AC25: 9499 | AD25: 8649 | AE25: 7749 | AF25: 10099 | AG25: 9499 | AH25: 8949 | AI25: 7749 | AJ25: 6599 | AK25: 9349 | AL25: 8449 | AM25: 7499 | AN25: 5599 | AO25: 3699 | AP25: 9099 | AQ25: 7999 | AR25: 6899 | AS25: 4699 | AT25: 2549 | AU25: 45954 | AV25: INDEFINIDO | AW25: =UPPER(TEXT(AU25, " dd \ mmmm \ aa")&" - "&TEXT(AV25, " dd \ mmmm \ aa")) -> 24 OCTUBRE 25 - INDEFINIDO
A26: 98679 | B26: 00986790 | C26: N.I14128A | D26: APPLE | E26: IPHONE 14 128GB AZUL ATT | F26: Apple iPhone 14 128GB | G26: APPLE IPHONE 14 128GB 4G | H26: =IF(K26="REVISAR","REVISAR",IF(K26>=20000,"FLAGSHIP",IF(K26>=12000,"PREMIUM",IF(K26>=7000,"HIGH",IF(K26>=5000,"MID",IF(K26>=3000,"LOW","ENTRY")))))) -> PREMIUM | I26: AT&T | J26: =K26/1.16 -> 12930.172 | K26: 14999 | L26: 10849 | M26: 10599 | N26: 10399 | O26: 9949 | P26: 9499 | Q26: 10699 | R26: 10399 | S26: 10099 | T26: 9499 | U26: 8949 | V26: 10549 | W26: 10149 | X26: 9799 | Y26: 9099 | Z26: 8349 | AA26: 10399 | AB26: 9949 | AC26: 9499 | AD26: 8649 | AE26: 7749 | AF26: 10099 | AG26: 9499 | AH26: 8949 | AI26: 7749 | AJ26: 6599 | AK26: 9349 | AL26: 8449 | AM26: 7499 | AN26: 5599 | AO26: 3699 | AP26: 9099 | AQ26: 7999 | AR26: 6899 | AS26: 4699 | AT26: 2549 | AU26: 45954 | AV26: INDEFINIDO | AW26: =UPPER(TEXT(AU26, " dd \ mmmm \ aa")&" - "&TEXT(AV26, " dd \ mmmm \ aa")) -> 24 OCTUBRE 25 - INDEFINIDO
A27: 98670 | B27: 00986700 | C27: N.I14128B | D27: APPLE | E27: IPHONE 14 128GB BLANCO ESTELAR ATT | F27: Apple iPhone 14 128GB | G27: APPLE IPHONE 14 128GB 4G | H27: =IF(K27="REVISAR","REVISAR",IF(K27>=20000,"FLAGSHIP",IF(K27>=12000,"PREMIUM",IF(K27>=7000,"HIGH",IF(K27>=5000,"MID",IF(K27>=3000,"LOW","ENTRY")))))) -> PREMIUM | I27: AT&T | J27: =K27/1.16 -> 12930.172 | K27: 14999 | L27: 10849 | M27: 10599 | N27: 10399 | O27: 9949 | P27: 9499 | Q27: 10699 | R27: 10399 | S27: 10099 | T27: 9499 | U27: 8949 | V27: 10549 | W27: 10149 | X27: 9799 | Y27: 9099 | Z27: 8349 | AA27: 10399 | AB27: 9949 | AC27: 9499 | AD27: 8649 | AE27: 7749 | AF27: 10099 | AG27: 9499 | AH27: 8949 | AI27: 7749 | AJ27: 6599 | AK27: 9349 | AL27: 8449 | AM27: 7499 | AN27: 5599 | AO27: 3699 | AP27: 9099 | AQ27: 7999 | AR27: 6899 | AS27: 4699 | AT27: 2549 | AU27: 45954 | AV27: INDEFINIDO | AW27: =UPPER(TEXT(AU27, " dd \ mmmm \ aa")&" - "&TEXT(AV27, " dd \ mmmm \ aa")) -> 24 OCTUBRE 25 - INDEFINIDO
A28: 98673 | B28: 00986730 | C28: N.I14128M | D28: APPLE | E28: IPHONE 14 128GB MORADO ATT | F28: Apple iPhone 14 128GB | G28: APPLE IPHONE 14 128GB 4G | H28: =IF(K28="REVISAR","REVISAR",IF(K28>=20000,"FLAGSHIP",IF(K28>=12000,"PREMIUM",IF(K28>=7000,"HIGH",IF(K28>=5000,"MID",IF(K28>=3000,"LOW","ENTRY")))))) -> PREMIUM | I28: AT&T | J28: =K28/1.16 -> 12930.172 | K28: 14999 | L28: 10849 | M28: 10599 | N28: 10399 | O28: 9949 | P28: 9499 | Q28: 10699 | R28: 10399 | S28: 10099 | T28: 9499 | U28: 8949 | V28: 10549 | W28: 10149 | X28: 9799 | Y28: 9099 | Z28: 8349 | AA28: 10399 | AB28: 9949 | AC28: 9499 | AD28: 8649 | AE28: 7749 | AF28: 10099 | AG28: 9499 | AH28: 8949 | AI28: 7749 | AJ28: 6599 | AK28: 9349 | AL28: 8449 | AM28: 7499 | AN28: 5599 | AO28: 3699 | AP28: 9099 | AQ28: 7999 | AR28: 6899 | AS28: 4699 | AT28: 2549 | AU28: 45954 | AV28: INDEFINIDO | AW28: =UPPER(TEXT(AU28, " dd \ mmmm \ aa")&" - "&TEXT(AV28, " dd \ mmmm \ aa")) -> 24 OCTUBRE 25 - INDEFINIDO
A29: 98676 | B29: 00986760 | C29: N.I14128R | D29: APPLE | E29: IPHONE 14 128GB ROJO ATT | F29: Apple iPhone 14 128GB | G29: APPLE IPHONE 14 128GB 4G | H29: =IF(K29="REVISAR","REVISAR",IF(K29>=20000,"FLAGSHIP",IF(K29>=12000,"PREMIUM",IF(K29>=7000,"HIGH",IF(K29>=5000,"MID",IF(K29>=3000,"LOW","ENTRY")))))) -> PREMIUM | I29: AT&T | J29: =K29/1.16 -> 12930.172 | K29: 14999 | L29: 10849 | M29: 10599 | N29: 10399 | O29: 9949 | P29: 9499 | Q29: 10699 | R29: 10399 | S29: 10099 | T29: 9499 | U29: 8949 | V29: 10549 | W29: 10149 | X29: 9799 | Y29: 9099 | Z29: 8349 | AA29: 10399 | AB29: 9949 | AC29: 9499 | AD29: 8649 | AE29: 7749 | AF29: 10099 | AG29: 9499 | AH29: 8949 | AI29: 7749 | AJ29: 6599 | AK29: 9349 | AL29: 8449 | AM29: 7499 | AN29: 5599 | AO29: 3699 | AP29: 9099 | AQ29: 7999 | AR29: 6899 | AS29: 4699 | AT29: 2549 | AU29: 45954 | AV29: INDEFINIDO | AW29: =UPPER(TEXT(AU29, " dd \ mmmm \ aa")&" - "&TEXT(AV29, " dd \ mmmm \ aa")) -> 24 OCTUBRE 25 - INDEFINIDO
A30: 98667 | B30: 00986670 | C30: N.I14128N | D30: APPLE | E30: IPHONE 14 128GB MEDIANOCHE ATT | F30: Apple iPhone 14 128GB | G30: APPLE IPHONE 14 128GB 4G | H30: =IF(K30="REVISAR","REVISAR",IF(K30>=20000,"FLAGSHIP",IF(K30>=12000,"PREMIUM",IF(K30>=7000,"HIGH",IF(K30>=5000,"MID",IF(K30>=3000,"LOW","ENTRY")))))) -> PREMIUM | I30: AT&T | J30: =K30/1.16 -> 12930.172 | K30: 14999 | L30: 10849 | M30: 10599 | N30: 10399 | O30: 9949 | P30: 9499 | Q30: 10699 | R30: 10399 | S30: 10099 | T30: 9499 | U30: 8949 | V30: 10549 | W30: 10149 | X30: 9799 | Y30: 9099 | Z30: 8349 | AA30: 10399 | AB30: 9949 | AC30: 9499 | AD30: 8649 | AE30: 7749 | AF30: 10099 | AG30: 9499 | AH30: 8949 | AI30: 7749 | AJ30: 6599 | AK30: 9349 | AL30: 8449 | AM30: 7499 | AN30: 5599 | AO30: 3699 | AP30: 9099 | AQ30: 7999 | AR30: 6899 | AS30: 4699 | AT30: 2549 | AU30: 45954 | AV30: INDEFINIDO | AW30: =UPPER(TEXT(AU30, " dd \ mmmm \ aa")&" - "&TEXT(AV30, " dd \ mmmm \ aa")) -> 24 OCTUBRE 25 - INDEFINIDO
A31: 99423 | B31: 00994230 | C31: N.I14256AM | D31: APPLE | E31: IPHONE 14 256GB AMARILLO ATT | F31: Apple iPhone 14 256GB | G31: APPLE IPHONE 14 256GB 4G | H31: PREMIUM | I31: AT&T | J31: =K31/1.16 -> 15085.345 | K31: 17499 | L31: 10759 | M31: 10559 | N31: 10299 | O31: 9859 | P31: 9459 | Q31: 10599 | R31: 10299 | S31: 9999 | T31: 9459 | U31: 8859 | V31: 10459 | W31: 10099 | X31: 9759 | Y31: 8999 | Z31: 8259 | AA31: 10299 | AB31: 9859 | AC31: 9459 | AD31: 8559 | AE31: 7699 | AF31: 9999 | AG31: 9459 | AH31: 8859 | AI31: 7699 | AJ31: 6499 | AK31: 9299 | AL31: 8359 | AM31: 7399 | AN31: 5499 | AO31: 3599 | AP31: 8999 | AQ31: 7899 | AR31: 6799 | AS31: 4659 | AT31: 2459 | AU31: 45572 | AV31: INDEFINIDO | AW31: 07 Octubre 2024 - INDEFINIDO
A32: 98697 | B32: 00986970 | C32: N.I14256A | D32: APPLE | E32: IPHONE 14 256GB AZUL ATT | F32: Apple iPhone 14 256GB | G32: APPLE IPHONE 14 256GB 4G | H32: PREMIUM | I32: AT&T | J32: =K32/1.16 -> 15085.345 | K32: 17499 | L32: 10759 | M32: 10559 | N32: 10299 | O32: 9859 | P32: 9459 | Q32: 10599 | R32: 10299 | S32: 9999 | T32: 9459 | U32: 8859 | V32: 10459 | W32: 10099 | X32: 9759 | Y32: 8999 | Z32: 8259 | AA32: 10299 | AB32: 9859 | AC32: 9459 | AD32: 8559 | AE32: 7699 | AF32: 9999 | AG32: 9459 | AH32: 8859 | AI32: 7699 | AJ32: 6499 | AK32: 9299 | AL32: 8359 | AM32: 7399 | AN32: 5499 | AO32: 3599 | AP32: 8999 | AQ32: 7899 | AR32: 6799 | AS32: 4659 | AT32: 2459 | AU32: 45572 | AV32: INDEFINIDO | AW32: 07 Octubre 2024 - INDEFINIDO
A33: 98688 | B33: 00986880 | C33: N.I14256B | D33: APPLE | E33: IPHONE 14 256GB BLANCO ESTELAR ATT | F33: Apple iPhone 14 256GB | G33: APPLE IPHONE 14 256GB 4G | H33: PREMIUM | I33: AT&T | J33: =K33/1.16 -> 15085.345 | K33: 17499 | L33: 10759 | M33: 10559 | N33: 10299 | O33: 9859 | P33: 9459 | Q33: 10599 | R33: 10299 | S33: 9999 | T33: 9459 | U33: 8859 | V33: 10459 | W33: 10099 | X33: 9759 | Y33: 8999 | Z33: 8259 | AA33: 10299 | AB33: 9859 | AC33: 9459 | AD33: 8559 | AE33: 7699 | AF33: 9999 | AG33: 9459 | AH33: 8859 | AI33: 7699 | AJ33: 6499 | AK33: 9299 | AL33: 8359 | AM33: 7399 | AN33: 5499 | AO33: 3599 | AP33: 8999 | AQ33: 7899 | AR33: 6799 | AS33: 4659 | AT33: 2459 | AU33: 45572 | AV33: INDEFINIDO | AW33: 07 Octubre 2024 - INDEFINIDO
A34: 98685 | B34: 00986850 | C34: N.I14256N | D34: APPLE | E34: IPHONE 14 256GB MEDIANOCHE ATT | F34: Apple iPhone 14 256GB | G34: APPLE IPHONE 14 256GB 4G | H34: PREMIUM | I34: AT&T | J34: =K34/1.16 -> 15085.345 | K34: 17499 | L34: 10759 | M34: 10559 | N34: 10299 | O34: 9859 | P34: 9459 | Q34: 10599 | R34: 10299 | S34: 9999 | T34: 9459 | U34: 8859 | V34: 10459 | W34: 10099 | X34: 9759 | Y34: 8999 | Z34: 8259 | AA34: 10299 | AB34: 9859 | AC34: 9459 | AD34: 8559 | AE34: 7699 | AF34: 9999 | AG34: 9459 | AH34: 8859 | AI34: 7699 | AJ34: 6499 | AK34: 9299 | AL34: 8359 | AM34: 7399 | AN34: 5499 | AO34: 3599 | AP34: 8999 | AQ34: 7899 | AR34: 6799 | AS34: 4659 | AT34: 2459 | AU34: 45572 | AV34: INDEFINIDO | AW34: 07 Octubre 2024 - INDEFINIDO
A35: 98691 | B35: 00986910 | C35: N.I14256M | D35: APPLE | E35: IPHONE 14 256GB MORADO ATT | F35: Apple iPhone 14 256GB | G35: APPLE IPHONE 14 256GB 4G | H35: PREMIUM | I35: AT&T | J35: =K35/1.16 -> 15085.345 | K35: 17499 | L35: 10759 | M35: 10559 | N35: 10299 | O35: 9859 | P35: 9459 | Q35: 10599 | R35: 10299 | S35: 9999 | T35: 9459 | U35: 8859 | V35: 10459 | W35: 10099 | X35: 9759 | Y35: 8999 | Z35: 8259 | AA35: 10299 | AB35: 9859 | AC35: 9459 | AD35: 8559 | AE35: 7699 | AF35: 9999 | AG35: 9459 | AH35: 8859 | AI35: 7699 | AJ35: 6499 | AK35: 9299 | AL35: 8359 | AM35: 7399 | AN35: 5499 | AO35: 3599 | AP35: 8999 | AQ35: 7899 | AR35: 6799 | AS35: 4659 | AT35: 2459 | AU35: 45572 | AV35: INDEFINIDO | AW35: 07 Octubre 2024 - INDEFINIDO
A36: 98694 | B36: 00986940 | C36: N.I14256R | D36: APPLE | E36: IPHONE 14 256GB ROJO ATT | F36: Apple iPhone 14 256GB | G36: APPLE IPHONE 14 256GB 4G | H36: PREMIUM | I36: AT&T | J36: =K36/1.16 -> 15085.345 | K36: 17499 | L36: 10759 | M36: 10559 | N36: 10299 | O36: 9859 | P36: 9459 | Q36: 10599 | R36: 10299 | S36: 9999 | T36: 9459 | U36: 8859 | V36: 10459 | W36: 10099 | X36: 9759 | Y36: 8999 | Z36: 8259 | AA36: 10299 | AB36: 9859 | AC36: 9459 | AD36: 8559 | AE36: 7699 | AF36: 9999 | AG36: 9459 | AH36: 8859 | AI36: 7699 | AJ36: 6499 | AK36: 9299 | AL36: 8359 | AM36: 7399 | AN36: 5499 | AO36: 3599 | AP36: 8999 | AQ36: 7899 | AR36: 6799 | AS36: 4659 | AT36: 2459 | AU36: 45572 | AV36: INDEFINIDO | AW36: 07 Octubre 2024 - INDEFINIDO
A37: 98727 | B37: 00987270 | C37: N.I14128PLM | D37: APPLE | E37: IPHONE 14 PLUS 128GB MORADO ATT | F37: Apple iPhone 14 Plus 128GB | G37: APPLE IPHONE 14 PLUS 128GB 4G | H37: PREMIUM | I37: AT&T | J37: =K37/1.16 -> 15085.345 | K37: 17499 | L37: 11359 | M37: 11159 | N37: 10899 | O37: 10499 | P37: 10059 | Q37: 11199 | R37: 10899 | S37: 10659 | T37: 10059 | U37: 9459 | V37: 11059 | W37: 10699 | X37: 10359 | Y37: 9599 | Z37: 8899 | AA37: 10899 | AB37: 10499 | AC37: 10059 | AD37: 9199 | AE37: 8299 | AF37: 10659 | AG37: 10059 | AH37: 9459 | AI37: 8299 | AJ37: 7159 | AK37: 9899 | AL37: 8959 | AM37: 7999 | AN37: 6099 | AO37: 4259 | AP37: 9599 | AQ37: 8499 | AR37: 7459 | AS37: 5259 | AT37: 3059 | AU37: 45572 | AV37: INDEFINIDO | AW37: 07 Octubre 2024 - INDEFINIDO
A38: 98724 | B38: 00987240 | C38: N.I14128PLB | D38: APPLE | E38: IPHONE 14 PLUS 128GB BLANCO ESTELAR ATT | F38: Apple iPhone 14 Plus 128GB | G38: APPLE IPHONE 14 PLUS 128GB 4G | H38: PREMIUM | I38: AT&T | J38: =K38/1.16 -> 15085.345 | K38: 17499 | L38: 11359 | M38: 11159 | N38: 10899 | O38: 10499 | P38: 10059 | Q38: 11199 | R38: 10899 | S38: 10659 | T38: 10059 | U38: 9459 | V38: 11059 | W38: 10699 | X38: 10359 | Y38: 9599 | Z38: 8899 | AA38: 10899 | AB38: 10499 | AC38: 10059 | AD38: 9199 | AE38: 8299 | AF38: 10659 | AG38: 10059 | AH38: 9459 | AI38: 8299 | AJ38: 7159 | AK38: 9899 | AL38: 8959 | AM38: 7999 | AN38: 6099 | AO38: 4259 | AP38: 9599 | AQ38: 8499 | AR38: 7459 | AS38: 5259 | AT38: 3059 | AU38: 45572 | AV38: INDEFINIDO | AW38: 07 Octubre 2024 - INDEFINIDO
A39: 98730 | B39: 00987300 | C39: N.I14128PLR | D39: APPLE | E39: IPHONE 14 PLUS 128GB ROJO ATT | F39: Apple iPhone 14 Plus 128GB | G39: APPLE IPHONE 14 PLUS 128GB 4G | H39: PREMIUM | I39: AT&T | J39: =K39/1.16 -> 15085.345 | K39: 17499 | L39: 11359 | M39: 11159 | N39: 10899 | O39: 10499 | P39: 10059 | Q39: 11199 | R39: 10899 | S39: 10659 | T39: 10059 | U39: 9459 | V39: 11059 | W39: 10699 | X39: 10359 | Y39: 9599 | Z39: 8899 | AA39: 10899 | AB39: 10499 | AC39: 10059 | AD39: 9199 | AE39: 8299 | AF39: 10659 | AG39: 10059 | AH39: 9459 | AI39: 8299 | AJ39: 7159 | AK39: 9899 | AL39: 8959 | AM39: 7999 | AN39: 6099 | AO39: 4259 | AP39: 9599 | AQ39: 8499 | AR39: 7459 | AS39: 5259 | AT39: 3059 | AU39: 45572 | AV39: INDEFINIDO | AW39: 07 Octubre 2024 - INDEFINIDO
A40: 98721 | B40: 00987210 | C40: N.I14128PLN | D40: APPLE | E40: IPHONE 14 PLUS 128GB MEDIANOCHE ATT | F40: Apple iPhone 14 Plus 128GB | G40: APPLE IPHONE 14 PLUS 128GB 4G | H40: PREMIUM | I40: AT&T | J40: =K40/1.16 -> 15085.345 | K40: 17499 | L40: 11359 | M40: 11159 | N40: 10899 | O40: 10499 | P40: 10059 | Q40: 11199 | R40: 10899 | S40: 10659 | T40: 10059 | U40: 9459 | V40: 11059 | W40: 10699 | X40: 10359 | Y40: 9599 | Z40: 8899 | AA40: 10899 | AB40: 10499 | AC40: 10059 | AD40: 9199 | AE40: 8299 | AF40: 10659 | AG40: 10059 | AH40: 9459 | AI40: 8299 | AJ40: 7159 | AK40: 9899 | AL40: 8959 | AM40: 7999 | AN40: 6099 | AO40: 4259 | AP40: 9599 | AQ40: 8499 | AR40: 7459 | AS40: 5259 | AT40: 3059 | AU40: 45572 | AV40: INDEFINIDO | AW40: 07 Octubre 2024 - INDEFINIDO
A41: 98733 | B41: 00987330 | C41: N.I14128PLA | D41: APPLE | E41: IPHONE 14 PLUS 128GB AZUL AT&T | F41: Apple iPhone 14 Plus 128GB | G41: APPLE IPHONE 14 PLUS 128GB 4G | H41: PREMIUM | I41: AT&T | J41: =K41/1.16 -> 15085.345 | K41: 17499 | L41: 11359 | M41: 11159 | N41: 10899 | O41: 10499 | P41: 10059 | Q41: 11199 | R41: 10899 | S41: 10659 | T41: 10059 | U41: 9459 | V41: 11059 | W41: 10699 | X41: 10359 | Y41: 9599 | Z41: 8899 | AA41: 10899 | AB41: 10499 | AC41: 10059 | AD41: 9199 | AE41: 8299 | AF41: 10659 | AG41: 10059 | AH41: 9459 | AI41: 8299 | AJ41: 7159 | AK41: 9899 | AL41: 8959 | AM41: 7999 | AN41: 6099 | AO41: 4259 | AP41: 9599 | AQ41: 8499 | AR41: 7459 | AS41: 5259 | AT41: 3059 | AU41: 45572 | AV41: INDEFINIDO | AW41: 07 Octubre 2024 - INDEFINIDO
A42: 98739 | B42: 00987390 | C42: N.I14256PLN | D42: APPLE | E42: IPHONE 14 PLUS 256GB MEDNOC ATT | F42: Apple iPhone 14 Plus 256GB | G42: APPLE IPHONE 14 PLUS 256GB 4G | H42: PREMIUM | I42: AT&T | J42: =K42/1.16 -> 17240.517 | K42: 19999 | L42: 13159 | M42: 12959 | N42: 12699 | O42: 12299 | P42: 11859 | Q42: 12999 | R42: 12699 | S42: 12399 | T42: 11859 | U42: 11259 | V42: 12859 | W42: 12499 | X42: 12159 | Y42: 11399 | Z42: 10699 | AA42: 12699 | AB42: 12259 | AC42: 11859 | AD42: 10959 | AE42: 10099 | AF42: 12399 | AG42: 11859 | AH42: 11259 | AI42: 10099 | AJ42: 8959 | AK42: 11699 | AL42: 10759 | AM42: 9799 | AN42: 7899 | AO42: 5999 | AP42: 11399 | AQ42: 10299 | AR42: 9199 | AS42: 7059 | AT42: 4859 | AU42: 45572 | AV42: INDEFINIDO | AW42: 07 Octubre 2024 - INDEFINIDO
... A58: 98829 | B58: 00988290 | C58: N.I14256PMP | D58: APPLE | E58: IPHONE 14 PROMAX 256GB PLATA ATT | F58: Apple iPhone 14 Pro Max 256GB | G58: APPLE IPHONE 14 PRO MAX 256GB 4G | H58: FLAGSHIP | I58: AT&T | J58: =K58/1.16 -> 27585.345 | K58: 31999 | L58: 23599 | M58: 23399 | N58: 23199 | O58: 22699 | P58: 22299 | Q58: 23499 | R58: 23199 | S58: 22899 | T58: 22299 | U58: 21699 | V58: 23299 | W58: 22899 | X58: 22599 | Y58: 21799 | Z58: 21099 | AA58: 23199 | AB58: 22699 | AC58: 22299 | AD58: 21399 | AE58: 20499 | AF58: 22899 | AG58: 22299 | AH58: 21699 | AI58: 20499 | AJ58: 19299 | AK58: 22099 | AL58: 21099 | AM58: 20199 | AN58: 18199 | AO58: 16299 | AP58: 21799 | AQ58: 20699 | AR58: 19599 | AS58: 17299 | AT58: 15099 | AU58: 45505 | AV58: INDEFINIDO | AW58: 01 Agosto 2024 - INDEFINIDO
...

Sheet Catalogo
A1: Marca | B1: Alcatel | C1: Apple | D1: Hisense | E1: Huawei | F1: Motorola | G1: Samsung | H1: Honor | I1: Xiaomi | J1: OPPO | K1: ZTE | L1: REALME | M1: NUBIA | N1: Google
A2: ALCATEL | B2: ALCATEL 1 SE 32GB 4G | C2: APPLE IPHONE 11 64GB 4G | D2: HISENSE E20 16GB 4G | E2: HUAWEI MATE 50 PRO 256GB 4G | F2: MOTO EDGE 70 PRO BUNDLEMOTO WATCH | G2: SAMSUNG GALAXY A01 16GB 4G | H2: HONOR 200 256GB 5G / BUNDLE | I2: XIAOMI 11 LITE NE 128GB 5G | J2: OPPO A12 32GB 4G | K2: ZTE AXON 60 256GB 4G | L2: REALME C11 2021 64GB 4G | N2: GOOGLE PIXEL 10 128GB 5G
A3: APPLE | B3: ALCATEL 1 SE 64GB 4G | C3: APPLE IPHONE 11 PRO 256GB 4G | D3: HISENSE E20S 32GB 4G | E3: HUAWEI NOVA 8 128GB 4G / BUNDLE | F3: MOTOROLA EDGE 50 512GB 5G | G3: SAMSUNG GALAXY A01 CORE 32GB 4G | H3: HONOR 400 512GB 5G | I3: XIAOMI 11 LITE NE 128GB 5G | J3: OPPO A38 128GB 4G | K3: ZTE AXON 60 LITE 256GB 4G | L3: REALME C35 128GB 4G | N3: GOOGLE PIXEL 10 256GB 5G
A4: GOOGLE | B4: ALCATEL 1B 5002M | C4: APPLE IPHONE 11 PRO 64GB 4G | D4: HISENSE E50 64GB 4G | E4: HUAWEI NOVA 8I 128GB 4G | F4: MOTOROLA EDGE 60 FUSION 256GB 5G | G4: SAMSUNG GALAXY A03 128GB 4G | H4: HONOR 400 LITE 256GB 5G | I4: XIAOMI 11T 256GB 4G | J4: OPPO A40 256GB 4G | K4: ZTE BLADE A55 128GB 4G | N4: GOOGLE PIXEL 10 PRO 256GB 5G
A5: HISENSE | B5: ALCATEL 3 2020 | C5: APPLE IPHONE 11 PRO MAX 64GB 4G | D5: HISENSE E50I | E5: HUAWEI NOVA 9 128GB 4G | F5: MOTOROLA EDGE 60 PRO 512GB 5G | G5: SAMSUNG GALAXY A03 64GB 4G | H5: HONOR 50 6GB 4G | I5: XIAOMI 11T 256GB 4G | J5: OPPO A5 256GB 4G | K5: ZTE BLADE A7 2020 64GB 4G | N5: GOOGLE PIXEL 10 PRO 512GB 5G
A6: HONOR | C6: APPLE IPHONE 12 256GB 4G | D6: HISENSE E60 64GB 4G | E6: HUAWEI NOVA 9 SE 128GB 4G | F6: MOTOROLA EDGE 70 512GB 5G | G6: SAMSUNG GALAXY A04 64GB 4G | H6: HONOR 50 8GB 4G | I6: XIAOMI 11T PRO 128GB 4G | J6: OPPO A5 PRO 256GB 4G | K6: ZTE BLADE V50 SMART 128GB 4G | N6: GOOGLE PIXEL 10 PRO XL 256GB 5G
A7: HUAWEI | C7: APPLE IPHONE 12 MINI 128GB | D7: HISENSE E60 LITE 64GB 4G | E7: HUAWEI NOVA Y60 64GB 4G | F7: MOTOROLA EDGE 70 FUSION 256GB 5G | G7: SAMSUNG GALAXY A05 64GB 4G | H7: HONOR 50 LITE 128GB 4G | I7: XIAOMI 11T PRO 128GB 4G | J7: OPPO A5 PRO 5G / BDL | N7: GOOGLE PIXEL 10 PRO XL 512GB 5G
A8: MOTOROLA | C8: APPLE IPHONE 12 MINI 256GB 4G | D8: HISENSE H60 SMART 128GB 4G | E8: HUAWEI NOVA Y61 64GB 4G | F8: MOTOROLA G04 128GB 4G | G8: SAMSUNG GALAXY A06 64GB 4G | H8: HONOR 600 512GB 5G | I8: XIAOMI 12 256GB 4G | J8: OPPO A54 128GB 4G | N8: GOOGLE PIXEL 9A 128GB 5G
A9: NUBIA | C9: APPLE IPHONE 12 MINI 64GB 4G | E9: HUAWEI NOVA Y70 128GB 4G | F9: MOTOROLA G24 256GB 4G | G9: SAMSUNG GALAXY A07 128GB 4G | H9: HONOR 8A 128GB 4G | I9: XIAOMI 12 256GB 4G | J9: OPPO A57 64GB 4G
A10: OPPO | C10: APPLE IPHONE 12 PRO 256GB 4G | E10: HUAWEI NOVA Y90 256GB 4G | F10: MOTOROLA G54 128GB 5G | G10: SAMSUNG GALAXY A07 64GB 4G | H10: HONOR 90 256GB 5G | I10: XIAOMI 15T BUNDLE BOCINA SOUND OUTDOOR | J10: OPPO A6 BUNDLE ENCO BUDS 3
A11: REALME | C11: APPLE IPHONE 12 PRO 512GB 4G | E11: HUAWEI P40 128GB LITE 4G | F11: MOTOROLA G54 256GB 5G | G11: SAMSUNG GALAXY A13 128GB 4G | H11: HONOR 90 512GB 4G | I11: XIAOMI 15T BUNDLE BOCINA SOUND OUTDOOR | J11: OPPO A60 256GB 4G
A12: SAMSUNG | C12: APPLE IPHONE 13 128GB 4G | E12: HUAWEI P50 128GB 4G | F12: MOTOROLA G84 256GB 5G | G12: SAMSUNG GALAXY A16 128GB 4G | H12: HONOR MAGIC 5 LITE 128GB 4G / BUNDLE | I12: XIAOMI 15T PRO BUNDLE REDMI PAD | J12: OPPO A6K 256GB 5G
A13: XIAOMI | C13: APPLE IPHONE 13 256GB 4G | E13: HUAWEI P50 PRO 256GB 4G | F13: MOTOROLA MOTO E22 32GB 4G | G13: SAMSUNG GALAXY A17 128GB 4G | H13: HONOR MAGIC 5 LITE 256GB 4G | I13: XIAOMI 15T PRO BUNDLE REDMI PAD | J13: OPPO A6T 128GB 4G
A14: ZTE | C14: APPLE IPHONE 13 512GB 4G | E14: HUAWEI P50 PRO 256GB 4G BUNDLE | F14: MOTOROLA MOTO E32 64GB 4G | G14: SAMSUNG GALAXY A23 128GB 4G | H14: HONOR MAGIC 6 LITE 256GB 5G | I14: XIAOMI 17T 512GB 5G BUNDLE | J14: OPPO A6X 128GB 4G
C15: APPLE IPHONE 13 MINI 128GB 4G | E15: HUAWEI Y5P 32GB 4G | F15: MOTOROLA MOTO E5 16GB 4G | G15: SAMSUNG GALAXY A26 128GB 5G | H15: HONOR MAGIC 8 LITE BUNDLE | I15: XIAOMI 17T 512GB 5G BUNDLE | J15: OPPO A72 128GB 4G
C16: APPLE IPHONE 13 PRO 128GB 4G | E16: HUAWEI Y6S 64GB 4G | F16: MOTOROLA MOTO E6I 32GB 4G | G16: Samsung Galaxy A27 128GB 5G | H16: HONOR MAGIC VS | I16: XIAOMI 17T PRO REDMI PAD 2 512GB 5G | J16: OPPO A79 256GB 5G
C17: APPLE IPHONE 13 PRO 256GB 4G | E17: HUAWEI Y7A 64GB 4G | F17: MOTOROLA MOTO E7I POWER 32GB 4G | G17: SAMSUNG GALAXY A33 128GB 4G | H17: HONOR MAGIC7 LITE 512GB 5G / BUNDLE | I17: XIAOMI 17T PRO REDMI PAD 2 512GB 5G | J17: OPPO A80 256GB 5G
C18: APPLE IPHONE 13 PRO 512GB 4G | E18: HUAWEI Y7P 64GB 4G | F18: MOTOROLA MOTO EDGE 20 PRO 256GB 4G | G18: SAMSUNG GALAXY A34 128GB 5G | H18: HONOR MAGIC7 PRO 512GB 5G | I18: XIAOMI NOTE 13 256GB 4G | J18: OPPO FIND X8 PRO 512GB 5G
C19: APPLE IPHONE 13 PRO MAX 128GB 4G | E19: HUAWEI Y7S 64GB 4G | F19: MOTOROLA MOTO EDGE 30 128GB 4G | G19: SAMSUNG GALAXY A35 128GB 5G | H19: HONOR MAGIC8 PRO BUNDLE PAD X8B | I19: XIAOMI NOTE 13 256GB 4G | J19: OPPO FIND X9 PRO 5G
C20: APPLE IPHONE 13 PRO MAX 1TB | E20: HUAWEI Y9A 128GB 4G / BUNDLE | F20: MOTOROLA MOTO EDGE 30 PRO 256GB 4G | G20: SAMSUNG GALAXY A36 128GB 5G | H20: HONOR MAGICV3 512GB 5G | I20: XIAOMI NOTE 13 PRO 256GB 4G | J20: OPPO RENO 10 256GB 4G
C21: APPLE IPHONE 13 PRO MAX 256GB 4G | F21: MOTOROLA MOTO EDGE 30 ULTRA 256GB 4G / BUNDLE | G21: SAMSUNG GALAXY A37 256GB 5G | H21: HONOR X5B PLUS 256GB 4G | I21: XIAOMI NOTE 13 PRO 256GB 4G | J21: OPPO RENO 12 512GB 5G
C22: APPLE IPHONE 14 128GB 4G | F22: MOTOROLA MOTO G05 128GB 4G | G22: SAMSUNG GALAXY A53 128GB 4G | H22: HONOR X5C 128GB 4G | I22: XIAOMI NOTE 15 PRO 5G / BUNDLE | J22: OPPO RENO 12 F 256GB 5G
C23: APPLE IPHONE 14 512GB 4G | F23: MOTOROLA MOTO G05 64GB 4G | G23: SAMSUNG GALAXY A54 128GB 5G | H23: HONOR X5C PLUS 256GB 4G | I23: XIAOMI NOTE 15 PRO 5G / BUNDLE | J23: OPPO RENO 13 512GB 5G
C24: APPLE IPHONE 14 PLUS 512GB 4G | F24: MOTOROLA MOTO G06 128GB 4G | G24: SAMSUNG GALAXY A55 128GB 5G | H24: HONOR X5D 128GB 4G | I24: XIAOMI REDMI 10C 128GB 4G | J24: OPPO RENO 13F 256GB 5G
C25: APPLE IPHONE 14 PRO 128GB 4G | F25: MOTOROLA MOTO G06 64GB 4G | G25: SAMSUNG GALAXY A56 256GB 5G | H25: HONOR X6A 128GB 4G | I25: XIAOMI REDMI 10C 128GB 4G | J25: OPPO RENO 14 512GB 5G BDL HEADPHONES
C26: APPLE IPHONE 14 PRO 1TB 4G | F26: MOTOROLA MOTO G13 128GB 4G | G26: SAMSUNG GALAXY A57 256GB 5G | H26: HONOR X6A PLUS 256GB 4G | I26: XIAOMI REDMI 11T | J26: OPPO RENO 5 LITE 128GB 4G
C27: APPLE IPHONE 14 PRO 512GB 4G | F27: MOTOROLA MOTO G15 256GB 4G | G27: SAMSUNG GALAXY A70 128GB 4G | H27: HONOR X6B 256GB 4G | I27: XIAOMI REDMI 11T | J27: OPPO RENO 7 128GB 4G / BUNDLE
C28: APPLE IPHONE 14 PRO MAX 1TB 4G | F28: MOTOROLA MOTO G17 256GB 4G | G28: SAMSUNG GALAXY FLIP4 128GB 4G | H28: HONOR X6C 256GB 4G | I28: XIAOMI REDMI 13 256GB 4G | J28: OPPO RENO13 PRO 512GB 5G
C29: APPLE IPHONE 14 PRO MAX 512GB | F29: MOTOROLA MOTO G20 64GB 4G | G29: SAMSUNG GALAXY FLIP4 256GB 4G | H29: HONOR X7 128GB 4G | I29: XIAOMI REDMI 13 256GB 4G | J29: OPPO RENO14 512GB 5G
C30: APPLE IPHONE 15 128GB 4G | F30: MOTOROLA MOTO G200 128GB 5G | G30: SAMSUNG GALAXY FOLD 4 256GB 4G | H30: HONOR X7C 256GB 4G / BUNDLE | I30: XIAOMI REDMI 13C 128GB 4G | J30: OPPO RENO14 F 256GB 5G
C31: APPLE IPHONE 15 PLUS 128GB 4G | F31: MOTOROLA MOTO G55 256GB 5G | G31: SAMSUNG GALAXY S22 256GB 5G | H31: HONOR X7D 256GB 4G | I31: XIAOMI REDMI 13C 128GB 4G | J31: OPPO RENO16 256GB 5G BDL ENCO BUDS 3 PRO
C32: APPLE IPHONE 15 PRO 128GB 4G | F32: MOTOROLA MOTO G56 256GB 5G | G32: SAMSUNG GALAXY S22 PLUS 128GB 5G | H32: HONOR X8 128GB 4G | I32: XIAOMI REDMI 14C 128GB 4G | J32: OPPO RENO16 F 256GB 5G
C33: APPLE IPHONE 15 PRO 256GB 4G | F33: MOTOROLA MOTO G60 128GB 4G | G33: SAMSUNG GALAXY S22 PLUS 256GB 5G | H33: HONOR X8B 256GB 4G | I33: XIAOMI REDMI 14C 128GB 4G
C34: APPLE IPHONE 15 PRO 512GB 4G | F34: MOTOROLA MOTO G77 256GB 5G | G34: SAMSUNG GALAXY S22 ULTRA 128GB 4G | H34: HONOR X8C 512GB 4G | I34: XIAOMI REDMI 14T 512GB 4G / BUNDLE
C35: APPLE IPHONE 15 PRO MAX 512GB 4G | F35: MOTOROLA MOTO G82 128GB 5G | G35: SAMSUNG GALAXY S22 ULTRA 256GB 4G | H35: HONOR X8D 256GB 4G | I35: XIAOMI REDMI 14T 512GB 4G / BUNDLE
C36: APPLE IPHONE 16 128GB 5G | F36: MOTOROLA MOTO G9 PLUS 128GB 4G | G36: SAMSUNG GALAXY S23 128GB 4G | H36: HONOR X9 8GB 4G | I36: XIAOMI REDMI 15 256GB 4G
C37: APPLE IPHONE 16 256GB 5G | F37: MOTOROLA MOTO ONE HYPER 128GB 4G | G37: SAMSUNG GALAXY S23 256GB 4G | H37: HONOR 200 512GB 5G / BUNDLE | I37: XIAOMI REDMI 15 256GB 4G
C38: APPLE IPHONE 16 PLUS 128GB 5G | F38: MOTOROLA RAZR 60 ULTRA 1T 5G | G38: SAMSUNG GALAXY S23 PLUS 256GB 4G | H38: HONOR X5 32GB 4G | I38: XIAOMI REDMI 15C 128GB 4G
C39: APPLE IPHONE 16 PLUS 256GB 5G | G39: SAMSUNG GALAXY S23 ULTRA 1TB 4G | H39: HONOR X6E 128GB 4G | I39: XIAOMI REDMI 15C 128GB 4G
